Workbook

Sheet BC
A1: INFORMACIÓN GENERAL PARA CASO DE NEGOCIO (BC)
A2: Actualización: 06 noviembre 2024. 13:11
A3: TIPO DE CLIENTE
A4: ENTIDAD CONTRATANTE
A5: CLIENTE
A6: Código del Proceso
A7: Objeto de contratación
A8: Provincia /Ciudad
A9: * Ambiente de Laboratorio :
A10: Número de días por semana que trabaja el laboratorio
A11: Turnos por dia
A12: Horas por turno
... A52: Observaciones
A54: *Inversiones adicionales | B54: Características | C54: Estado | D54: Cantidad | E54: Precio | F54: Total
A55: Control externo de tercera opinión | D55: 0 | E55: 0 | F55: =D55*E55 -> 0
A56: Control interno interlaboratorial | D56: 0 | E56: 0 | F56: =D56*E56 -> 0
A57: Póliza $ 66.593,64 | D57: 0 | E57: 0 | F57: =D57*E57 -> 0
A58: Póliza de seguro de equipos | D58: 0 | E58: 0 | F58: =D58*E58 -> 0
A59: Ups equipo | B59: Equipo | D59: 0 | E59: 0 | F59: =D59*E59 -> 0
A60: Ups servidor | B60: Powest on line 1kva 1000VA | D60: 0 | E60: 200 | F60: =D60*E60 -> 0
A61: LIS | D61: 1 | E61: 1920 | F61: =D61*E61 -> 1920
A62: Interfaz | D62: 1 | E62: 0 | F62: =D62*E62 -> 0
A63: Lantronix | D63: 0 | E63: 820 | F63: =D63*E63 -> 0
A64: IP publica | D64: 0 | E64: 0 | F64: =D64*E64 -> 0
A65: Punto de consulta web | D65: 0 | E65: 0 | F65: =D65*E65 -> 0
A66: Internet | D66: 0 | E66: 0 | F66: =D66*E66 -> 0
A67: Servidor | D67: 0 | E67: 0 | F67: =D67*E67 -> 0
A68: Computadores Desktop HP P20AV 19.5 | B68: Monitor + Teclado y mouse | D68: 0 | E68: 900 | F68: =D68*E68 -> 0
A69: Impresora Epson L4260 Laser multifuncion | D69: 0 | E69: 300 | F69: =D69*E69 -> 0
A70: Tinta | B70: Juego de 4 colores | D70: 0 | E70: 65 | F70: =D70*E70 -> 0
A71: Impresora Epson Toner | D71: 0 | E71: 980 | F71: =D71*E71 -> 0
A72: Toner | B72: Juego de 4 colores | D72: 0 | E72: 568 | F72: =D72*E72 -> 0
A73: Impresora Zebra Termica ZD230 ETHERNET Y USB | D73: 0 | E73: 400 | F73: =D73*E73 -> 0
A74: Sistema de destilación de agua pequeño | D74: 0 | F74: =D74*E74 -> 0
A75: Sistema de osmosis | D75: 0 | E75: 0 | F75: =D75*E75 -> 0
A76: Sitema de prefiltracion | D76: 0 | E76: 0 | F76: =D76*E76 -> 0
A77: Tanque para resina mixta (muerta) | D77: 0 | E77: 0 | F77: =D77*E77 -> 0
A78: Tubo contenedor de resina | D78: 0 | F78: =D78*E78 -> 0
A79: Estructura de proteccion para sistema de agua | D79: 0 | E79: 400 | F79: =D79*E79 -> 0
A80: MEMBRANE EQ.OSMOSIS, AG2521TF 2.5 diam | D80: 0 | E80: 600 | F80: =D80*E80 -> 0
...

Sheet BIOMETRIA HEMATICA
A1: Parámetro | B1: DET/AÑO PROCESO
A2: BIOMETRIA HEMATICA | B2: 12200 | C2: RETICULOCITOS | E2: PLAQUETAS FLUORESCENTES | G2: FLUIDOS CORPORALES
A6: TIEMPO CONTRATO EN MESES | B6: 12
A10: NUMERO DE EQUIPOS | B10: 1

Sheet DETERMINACION XP-300
A2: Parámetro | B2: ID | C2: PRODUCTO | D2: DET/KIT | E2: DIAS ESTABILIDAD | F2: DET/AÑO PROCESO | G2: PRODUCTO CALCULADO | H2: MINIMOS POR ESTABILIDAD | I2: PRODUCTO A ENTREGAR | J2: REDONDEADO A ENTREGAR | K2: PVP | L2: TOTAL | M2: PVP BIOMETRIA | N2: PARA PROCESO | O2: VALOR INICIAL DEL PROCESO | P2: VALOR FINAL DEL PROCESO
A3: Biometria básica | B3: 3145611001 | C3: CELLPACK 20L | D3: 450 | E3: 60 | F3: ='BIOMETRIA HEMATICA'!$B$2 -> 12200 | G3: =F3/D3 -> 27.111111 | H3: =(360/E3)*'BIOMETRIA HEMATICA'!$B$10 -> 6 | I3: =IF(G3>H3,G3,H3) -> 27.111111 | J3: =ROUNDUP(I3,0) -> 28 | K3: 253 | L3: =K3*J3 -> 7084 | M3: =(SUM(L3:L8)/'BIOMETRIA HEMATICA'!B2)+L10 -> 2.2294262 | N3: =((M3*0.15)+M3) -> 2.5638402 | O3: =N3*'BIOMETRIA HEMATICA'!B2 -> 31278.85 | P3: =M3*'BIOMETRIA HEMATICA'!B2 -> 27199
B4: 12216540001 | C4: STROMA WH KX21 x 500ML | D4: 450 | E4: 60 | F4: ='BIOMETRIA HEMATICA'!$B$2 -> 12200 | G4: =F4/D4 -> 27.111111 | H4: =(360/E4)*'BIOMETRIA HEMATICA'!$B$10 -> 6 | I4: =IF(G4>H4,G4,H4) -> 27.111111 | J4: =ROUNDUP(I4,0) -> 28 | K4: 264 | L4: =K4*J4 -> 7392
B5: 3134466001 | C5: EIGHT CHECK-3WP XTRA ( 4 X 2 ML) | D5: =(((F3/30)/12)*E5) -> 2880.5556 | E5: 85 | F5: ='BIOMETRIA HEMATICA'!$B$2 -> 12200 | G5: =F5/D5 -> 4.2352941 | H5: =(360/E5)*'BIOMETRIA HEMATICA'!$B$10 -> 4.2352941 | I5: =IF(G5>H5,G5,H5) -> 4.2352941 | J5: =ROUNDUP(I5,0) -> 5 | K5: 269 | L5: =K5*J5 -> 1345
B6: 3113353180 | C6: PAPER ROLL F.PRINTER STP211-144 (10PCS.) | D6: 900 | E6: 365 | F6: ='BIOMETRIA HEMATICA'!$B$2 -> 12200 | G6: =F6/D6 -> 13.555556 | H6: =(360/E6)*'BIOMETRIA HEMATICA'!$B$10 -> 0.98630137 | I6: =IF(G6>H6,G6,H6) -> 13.555556 | J6: =ROUNDUP(I6,0) -> 14 | K6: 80 | L6: =K6*J6 -> 1120
C8: ADICIONALES | J8: ='BIOMETRIA HEMATICA'!B6 -> 12 | K8: =BC!F109 -> 1920 | L8: =(K8/J8)*J8 -> 1920
C9: ALQUILER | K9: 210 | L9: =(K9*J8)/(12) -> 210
C10: EQUIPO | K10: 8338 | L10: =((((K10)/(J8)*12))/'BIOMETRIA HEMATICA'!B2)*(J8/12) -> 0.68344262

Sheet PRUEBA EFECTIVA XP-300
A2: Parámetro | B2: ID | C2: PRODUCTO | D2: DET/KIT | E2: DIAS ESTABILIDAD | F2: DET/AÑO PROCESO | G2: PRODUCTO CALCULADO | H2: MINIMOS POR ESTABILIDAD | I2: PRODUCTO A ENTREGAR | J2: REDONDEADO A ENTREGAR | K2: PVP | L2: TOTAL | M2: PVP BIOMETRIA | N2: PARA PROCESO | O2: VALOR INICIAL DEL PROCESO | P2: VALOR FINAL DEL PROCESO
A3: Biometria básica | B3: 3145611001 | C3: CELLPACK 20L | D3: 450 | E3: 60 | F3: =('BIOMETRIA HEMATICA'!$B$2*0.2)+'BIOMETRIA HEMATICA'!$B$2 -> 14640 | G3: =F3/D3 -> 32.533333 | H3: =(360/E3)*'BIOMETRIA HEMATICA'!$B$10 -> 6 | I3: =IF(G3>H3,G3,H3) -> 32.533333 | J3: =ROUNDUP(I3,0) -> 33 | K3: 253 | L3: =K3*J3 -> 8349 | M3: =(SUM(L3:L8)/'BIOMETRIA HEMATICA'!B2)+L10 -> 2.4609836 | N3: =((M3*0.15)+M3) -> 2.8301311 | O3: =N3*'BIOMETRIA HEMATICA'!B2 -> 34527.6 | P3: =M3*'BIOMETRIA HEMATICA'!B2 -> 30024
B4: 12216540001 | C4: STROMA WH KX21 x 500ML | D4: 450 | E4: 60 | F4: =('BIOMETRIA HEMATICA'!$B$2*0.2)+'BIOMETRIA HEMATICA'!$B$2 -> 14640 | G4: =F4/D4 -> 32.533333 | H4: =(360/E4)*'BIOMETRIA HEMATICA'!$B$10 -> 6 | I4: =IF(G4>H4,G4,H4) -> 32.533333 | J4: =ROUNDUP(I4,0) -> 33 | K4: 264 | L4: =K4*J4 -> 8712
B5: 3134466001 | C5: EIGHT CHECK-3WP XTRA ( 4 X 2 ML) | D5: =(((F3/30)/12)*E5) -> 3456.6667 | E5: 85 | F5: =('BIOMETRIA HEMATICA'!$B$2*0.2)+'BIOMETRIA HEMATICA'!$B$2 -> 14640 | G5: =F5/D5 -> 4.2352941 | H5: =(360/E5)*'BIOMETRIA HEMATICA'!$B$10 -> 4.2352941 | I5: =IF(G5>H5,G5,H5) -> 4.2352941 | J5: =ROUNDUP(I5,0) -> 5 | K5: 269 | L5: =K5*J5 -> 1345
B6: 3113353180 | C6: PAPER ROLL F.PRINTER STP211-144 (10PCS.) | D6: 900 | E6: 365 | F6: =('BIOMETRIA HEMATICA'!$B$2*0.2)+'BIOMETRIA HEMATICA'!$B$2 -> 14640 | G6: =F6/D6 -> 16.266667 | H6: =(360/E6)*'BIOMETRIA HEMATICA'!$B$10 -> 0.98630137 | I6: =IF(G6>H6,G6,H6) -> 16.266667 | J6: =ROUNDUP(I6,0) -> 17 | K6: 80 | L6: =K6*J6 -> 1360
C8: ADICIONALES | J8: ='BIOMETRIA HEMATICA'!B6 -> 12 | K8: =BC!F109 -> 1920 | L8: =(K8/J8)*J8 -> 1920
C9: ALQUILER | K9: 210 | L9: =(K9*J8)/(12) -> 210
C10: EQUIPO | K10: 8338 | L10: =((((K10)/(J8)*12))/'BIOMETRIA HEMATICA'!B2)*(J8/12) -> 0.68344262

Sheet COMODATO TODO COMPRADO XP-300
A2: Parámetro | B2: ID | C2: PRODUCTO | D2: DET/KIT | E2: DIAS ESTABILIDAD | F2: DET/AÑO PROCESO | G2: PRODUCTO CALCULADO | H2: MINIMOS POR ESTABILIDAD | I2: PRODUCTO A ENTREGAR | J2: REDONDEADO A ENTREGAR | K2: PVP | L2: TOTAL | M2: PVP TODO COMPRADO | N2: TOTAL TODO COMPRADO | O2: PVP BIOMETRIA
A3: Biometria básica | B3: 3145611001 | C3: CELLPACK 20L | D3: 450 | E3: 60 | F3: ='BIOMETRIA HEMATICA'!$B$2 -> 12200 | G3: =F3/D3 -> 27.111111 | H3: =(360/E3)*'BIOMETRIA HEMATICA'!$B$10 -> 6 | I3: =IF(G3>H3,G3,H3) -> 27.111111 | J3: =ROUNDDOWN(I3,0) -> 27 | K3: 253 | L3: =K3*J3 -> 6831 | M3: =(K3*$L$13)+K3 -> 286.52348 | N3: =M3*J3 -> 7736.1341 | O3: =(SUM(N3:N6)/'BIOMETRIA HEMATICA'!B2)+L10 -> 2.1756557
B4: 12216540001 | C4: STROMA WH KX21 x 500ML | D4: 450 | E4: 60 | F4: ='BIOMETRIA HEMATICA'!$B$2 -> 12200 | G4: =F4/D4 -> 27.111111 | H4: =(360/E4)*'BIOMETRIA HEMATICA'!$B$10 -> 6 | I4: =IF(G4>H4,G4,H4) -> 27.111111 | J4: =ROUNDDOWN(I4,0) -> 27 | K4: 264 | L4: =K4*J4 -> 7128 | M4: =(K4*$L$13)+K4 -> 298.98103 | N4: =M4*J4 -> 8072.4877
B5: 3134466001 | C5: EIGHT CHECK-3WP XTRA ( 4 X 2 ML) | D5: =(((F3/30)/12)*E5) -> 2880.5556 | E5: 85 | F5: ='BIOMETRIA HEMATICA'!$B$2 -> 12200 | G5: =F5/D5 -> 4.2352941 | H5: =(360/E5)*'BIOMETRIA HEMATICA'!$B$10 -> 4.2352941 | I5: =IF(G5>H5,G5,H5) -> 4.2352941 | J5: =ROUNDDOWN(I5,0) -> 4 | K5: 269 | L5: =K5*J5 -> 1076 | M5: =(K5*$L$13)+K5 -> 304.64355 | N5: =M5*J5 -> 1218.5742
B6: 3113353180 | C6: PAPER ROLL F.PRINTER STP211-144 (10PCS.) | D6: 900 | E6: 365 | F6: ='BIOMETRIA HEMATICA'!$B$2 -> 12200 | G6: =F6/D6 -> 13.555556 | H6: =(360/E6)*'BIOMETRIA HEMATICA'!$B$10 -> 0.98630137 | I6: =IF(G6>H6,G6,H6) -> 13.555556 | J6: =ROUNDDOWN(I6,0) -> 13 | K6: 80 | L6: =K6*J6 -> 1040 | M6: =(K6*$L$13)+K6 -> 90.600311 | N6: =M6*J6 -> 1177.804
C8: ADICIONALES | J8: ='BIOMETRIA HEMATICA'!B6 -> 12 | K8: =BC!F109 -> 1920 | L8: =(K8/J8)*J8 -> 1920
C9: REPUESTOS | K9: 210 | L9: =(K9*J8)/(12) -> 210
C10: EQUIPO | K10: 8338 | L10: =((((K10)/(J8)*12))/'BIOMETRIA HEMATICA'!B2)*(J8/12) -> 0.68344262
L11: =SUM(L8:L9) -> 2130
L12: =SUM(L3:L6) -> 16075
L13: =L11/L12 -> 0.13250389
L14: =SUM(L3:L10) -> 18205.683

Sheet DETERMINACION XN
A1: XNL-350 SIN LICENCIAS
A2: Parámetro | B2: ID | C2: PRODUCTO | D2: DET/KIT | E2: DIAS ESTABILIDAD | F2: DET/AÑO PROCESO | G2: PRODUCTO CALCULADO | H2: MINIMOS POR ESTABILIDAD | I2: PRODUCTO A ENTREGAR | K2: REDONDEADO A ENTREGAR | L2: PVP | M2: TOTAL | O2: PVP BIOMETRIA COMPLETA | P2: PARA PROCESO | Q2: VALOR INICIAL DEL PROCESO | R2: VALOR FINAL DEL PROCESO
A3: Biometria básica | B3: 6510167001 | C3: CELLPACK DCL | D3: 450 | E3: 60 | F3: ='BIOMETRIA HEMATICA'!$B$2 -> 12200 | G3: =F3/D3 -> 27.111111 | H3: =(360/E3)*'BIOMETRIA HEMATICA'!$B$10 -> 6 | I3: =IF(G3>H3,G3,H3) -> 27.111111 | K3: =ROUNDUP(I3,0) -> 28 | L3: 121 | M3: =L3*K3 -> 3388 | O3: =(SUM(M3:N12)/F3)+M16+(BC!F109/'DETERMINACION XN'!F3) -> 1.8263852 | P3: =((O3*0.15)+O3) -> 2.100343 | Q3: =P3*'BIOMETRIA HEMATICA'!B2 -> 25624.185 | R3: =O3*'BIOMETRIA HEMATICA'!B2 -> 22281.9
B4: 3337006001 | C4: SULFOLYSER REAGENT X 5L | D4: 9450 | E4: 60 | F4: ='BIOMETRIA HEMATICA'!$B$2 -> 12200 | G4: =F4/D4 -> 1.2910053 | H4: =(360/E4)*'BIOMETRIA HEMATICA'!$B$10 -> 6 | I4: =IF(G4>H4,G4,H4) -> 6 | J4: =IF(N4>N5,0,I4) -> 6 | L4: 1107 | M4: =L4*K4 -> 0 | N4: =L4*K4 -> 0 | O4: PVP BIOMETRIA | P4: PARA PROCESO | Q4: VALOR INICIAL DEL PROCESO | R4: VALOR FINAL DEL PROCESO
B5: 12215616001 | C5: SULFOLYSER REAGENT 500 ml | D5: 850 | E5: 60 | F5: ='BIOMETRIA HEMATICA'!$B$2 -> 12200 | G5: =F5/D5 -> 14.352941 | H5: =(360/E5)*'BIOMETRIA HEMATICA'!$B$10 -> 6 | I5: =IF(G5>H5,G5,H5) -> 14.352941 | J5: =IF(N5>N4,0,I5) -> 0 | K5: =ROUNDUP(I5,0) -> 15 | L5: 228.33 | M5: =L5*K5 -> 3424.95 | N5: =L5*K5 -> 3424.95 | O5: =(SUM(M3:N9)/'BIOMETRIA HEMATICA'!B2)+M16 -> 1.6690082 | P5: =((O5*0.15)+O5) -> 1.9193594 | Q5: =P5*'BIOMETRIA HEMATICA'!B2 -> 23416.185 | R5: =O5*'BIOMETRIA HEMATICA'!B2 -> 20361.9
B6: 7837984001 | C6: WDF Lysercell WDF | D6: 2450 | E6: 90 | F6: ='BIOMETRIA HEMATICA'!$B$2 -> 12200 | G6: =F6/D6 -> 4.9795918 | H6: =(360/E6)*'BIOMETRIA HEMATICA'!$B$10 -> 4 | I6: =IF(G6>H6,G6,H6) -> 4.9795918 | K6: =ROUNDUP(I6,0) -> 5 | L6: 176 | M6: =L6*K6 -> 880
B7: 6510256001 | C7: WDF Fluorocell WDF 2X42 ML | D7: 3400 | E7: 180 | F7: ='BIOMETRIA HEMATICA'!$B$2 -> 12200 | G7: =F7/D7 -> 3.5882353 | H7: =(360/E7)*'BIOMETRIA HEMATICA'!$B$10 -> 2 | I7: =IF(G7>H7,G7,H7) -> 3.5882353 | K7: =ROUNDUP(I7,0) -> 4 | L7: 862 | M7: =L7*K7 -> 3448
B8: 6952291001 | C8: CELLCLEAN AUTO 4 ML X 20 | D8: =(((F3/30)/12)*E8) -> 5083.3333 | E8: 150 | F8: ='BIOMETRIA HEMATICA'!$B$2 -> 12200 | G8: =F8/D8 -> 2.4 | H8: =(360/E8)*'BIOMETRIA HEMATICA'!$B$10 -> 2.4 | I8: =IF(G8>H8,G8,H8) -> 2.4 | K8: =ROUNDUP(I8,0) -> 3 | L8: 52 | M8: =L8*K8 -> 156
B9: 7051506001 | C9: XN Check 12x3.0ml Level 1,2,3 | D9: =(((F3/30)/12)*E9) -> 1897.7778 | E9: 56 | F9: ='BIOMETRIA HEMATICA'!$B$2 -> 12200 | G9: =F9/D9 -> 6.4285714 | H9: =(360/E9)*'BIOMETRIA HEMATICA'!$B$10 -> 6.4285714 | I9: =IF(G9>H9,G9,H9) -> 6.4285714 | L9: 544 | M9: =L9*K9 -> 0
A10: Reticulocitos | B10: 6510272001 | C10: FLUOROCELL RET 2 X 12ML | D10: 650 | E10: 180 | F10: ='BIOMETRIA HEMATICA'!$D$2 -> 0 | G10: =F10/D10 -> 0 | H10: =(360/E10)*'BIOMETRIA HEMATICA'!$B$10 -> 2 | I10: =IF(G10>H10,G10,H10) -> 2 | J10: =IF(G10=0,0,G10) -> 0 | L10: 1705 | M10: =L10*K10 -> 0
B11: 9426752001 | C11: CELLPACK DFL 1 L | D11: 450 | E11: 60 | F11: ='BIOMETRIA HEMATICA'!$D$2 -> 0 | G11: =F11/D11 -> 0 | H11: =(360/E11)*'BIOMETRIA HEMATICA'!$B$10 -> 6 | I11: =IF(G11>H11,G11,H11) -> 6 | J11: =IF(G11=0,0,G11) -> 0 | L11: 34 | M11: =L11*K11 -> 0
A12: Líquidos | B12: 7051409001 | C12: XN-Check BF 6x3.0ml Level 1,2 | D12: =(((F3/30)/12)*E12) -> 1897.7778 | E12: 56 | F12: ='BIOMETRIA HEMATICA'!$H$2 -> 0 | G12: =F12/D12 -> 0 | H12: =(360/E12)*'BIOMETRIA HEMATICA'!$B$10 -> 6.4285714 | I12: =IF(G12>H12,G12,H12) -> 6.4285714 | J12: =IF(G12=0,0,G12) -> 0 | L12: 661 | M12: =L12*K12 -> 0
C14: ADICIONALES | K14: ='BIOMETRIA HEMATICA'!B6 -> 12 | L14: =BC!F109 -> 1920 | M14: =(L14/K14)*K14 -> 1920
C15: MANTENIMIENTO/REPUESTOS | L15: 470 | M15: =(L15*K14)/(12) -> 470
C16: EQUIPO | L16: 21362 | M16: =((((L15)*(K14))/'BIOMETRIA HEMATICA'!B2)) -> 0.46229508
A20: XNL-350 CON LICENCIAS
A21: Parámetro | B21: ID | C21: PRODUCTO | D21: DET/KIT | E21: DIAS ESTABILIDAD | F21: DET/AÑO PROCESO | G21: PRODUCTO CALCULADO | H21: MINIMOS POR ESTABILIDAD | I21: PRODUCTO A ENTREGAR | K21: REDONDEADO A ENTREGAR | L21: PVP | M21: TOTAL | O21: PVP BIOMETRIA COMPLETA | P21: PARA PROCESO | Q21: VALOR INICIAL DEL PROCESO | R21: VALOR FINAL DEL PROCESO
A22: Biometria básica | B22: 6510167001 | C22: CELLPACK DCL | D22: 450 | E22: 60 | F22: ='BIOMETRIA HEMATICA'!$B$2 -> 12200 | G22: =F22/D22 -> 27.111111 | H22: =(360/E22)*'BIOMETRIA HEMATICA'!$B$10 -> 6 | I22: =IF(G22>H22,G22,H22) -> 27.111111 | K22: =ROUNDUP(I22,0) -> 28 | L22: 121 | M22: =L22*K22 -> 3388 | O22: =(SUM(M22:M31)/'BIOMETRIA HEMATICA'!B2)+M35 -> 3.0186844 | P22: =((O22*0.15)+O22) -> 3.4714871 | Q22: =P22*'BIOMETRIA HEMATICA'!B21 -> 0 | R22: =O22*'BIOMETRIA HEMATICA'!B21 -> 0
B23: 3337006001 | C23: SULFOLYSER REAGENT X 5L | D23: 9450 | E23: 60 | F23: ='BIOMETRIA HEMATICA'!$B$2 -> 12200 | G23: =F23/D23 -> 1.2910053 | H23: =(360/E23)*'BIOMETRIA HEMATICA'!$B$10 -> 6 | I23: =IF(G23>H23,G23,H23) -> 6 | J23: =IF(N23>N24,0,I23) -> 0 | K23: =ROUNDUP(I23,0) -> 6 | L23: 1107 | M23: =L23*K23 -> 6642 | N23: =L23*K23 -> 6642 | O23: PVP BIOMETRIA | P23: PARA PROCESO | Q23: VALOR INICIAL DEL PROCESO | R23: VALOR FINAL DEL PROCESO
B24: 12215616001 | C24: SULFOLYSER REAGENT 500 ml | D24: 850 | E24: 60 | F24: ='BIOMETRIA HEMATICA'!$B$2 -> 12200 | G24: =F24/D24 -> 14.352941 | H24: =(360/E24)*'BIOMETRIA HEMATICA'!$B$10 -> 6 | I24: =IF(G24>H24,G24,H24) -> 14.352941 | J24: =IF(N24>N23,0,I24) -> 14.352941 | K24: =ROUNDUP(I24,0) -> 15 | L24: 228.33 | M24: =L24*K24 -> 3424.95 | N24: =L24*K24 -> 3424.95 | O24: =(SUM(M22:M28)/'BIOMETRIA HEMATICA'!B2)+M35 -> 2.3431926 | P24: =((O24*0.15)+O24) -> 2.6946715 | Q24: =P24*'BIOMETRIA HEMATICA'!B21 -> 0 | R24: =O24*'BIOMETRIA HEMATICA'!B21 -> 0
B25: 7837984001 | C25: WDF Lysercell WDF | D25: 2450 | E25: 90 | F25: ='BIOMETRIA HEMATICA'!$B$2 -> 12200 | G25: =F25/D25 -> 4.9795918 | H25: =(360/E25)*'BIOMETRIA HEMATICA'!$B$10 -> 4 | I25: =IF(G25>H25,G25,H25) -> 4.9795918 | K25: =ROUNDUP(I25,0) -> 5 | L25: 176 | M25: =L25*K25 -> 880
B26: 6510256001 | C26: WDF Fluorocell WDF 2X42 ML | D26: 3400 | E26: 180 | F26: ='BIOMETRIA HEMATICA'!$B$2 -> 12200 | G26: =F26/D26 -> 3.5882353 | H26: =(360/E26)*'BIOMETRIA HEMATICA'!$B$10 -> 2 | I26: =IF(G26>H26,G26,H26) -> 3.5882353 | K26: =ROUNDUP(I26,0) -> 4 | L26: 862 | M26: =L26*K26 -> 3448
B27: 6952291001 | C27: CELLCLEAN AUTO 4 ML X 20 | D27: =(((F22/30)/12)*E27) -> 5083.3333 | E27: 150 | F27: ='BIOMETRIA HEMATICA'!$B$2 -> 12200 | G27: =F27/D27 -> 2.4 | H27: =(360/E27)*'BIOMETRIA HEMATICA'!$B$10 -> 2.4 | I27: =IF(G27>H27,G27,H27) -> 2.4 | K27: =ROUNDUP(I27,0) -> 3 | L27: 52 | M27: =L27*K27 -> 156
B28: 7051506001 | C28: XN Check 12x3.0ml Level 1,2,3 | D28: =(((F22/30)/12)*E28) -> 1897.7778 | E28: 56 | F28: ='BIOMETRIA HEMATICA'!$B$2 -> 12200 | G28: =F28/D28 -> 6.4285714 | H28: =(360/E28)*'BIOMETRIA HEMATICA'!$B$10 -> 6.4285714 | I28: =IF(G28>H28,G28,H28) -> 6.4285714 | K28: =ROUNDUP(I28,0) -> 7 | L28: 544 | M28: =L28*K28 -> 3808
A29: Reticulocitos | B29: 6510272001 | C29: FLUOROCELL RET 2 X 12ML | D29: 650 | E29: 180 | F29: ='BIOMETRIA HEMATICA'!$D$2 -> 0 | G29: =F29/D29 -> 0 | H29: =(360/E29)*'BIOMETRIA HEMATICA'!$B$10 -> 2 | I29: =IF(G29>H29,G29,H29) -> 2 | J29: =IF(G29=0,0,G29) -> 0 | K29: =ROUNDUP(I29,0) -> 2 | L29: 1705 | M29: =L29*K29 -> 3410
B30: 9426752001 | C30: CELLPACK DFL 1 L | D30: 450 | E30: 60 | F30: ='BIOMETRIA HEMATICA'!$D$2 -> 0 | G30: =F30/D30 -> 0 | H30: =(360/E30)*'BIOMETRIA HEMATICA'!$B$10 -> 6 | I30: =IF(G30>H30,G30,H30) -> 6 | J30: =IF(G30=0,0,G30) -> 0 | K30: =ROUNDUP(I30,0) -> 6 | L30: 34 | M30: =L30*K30 -> 204
A31: Líquidos | B31: 7051409001 | C31: XN-Check BF 6x3.0ml Level 1,2 | D31: =(((F22/30)/12)*E31) -> 1897.7778 | E31: 56 | F31: ='BIOMETRIA HEMATICA'!$H$2 -> 0 | G31: =F31/D31 -> 0 | H31: =(360/E31)*'BIOMETRIA HEMATICA'!$B$10 -> 6.4285714 | I31: =IF(G31>H31,G31,H31) -> 6.4285714 | J31: =IF(G10=0,0,G31) -> 0 | K31: =ROUNDUP(I31,0) -> 7 | L31: 661 | M31: =L31*K31 -> 4627
C33: ADICIONALES | K33: ='BIOMETRIA HEMATICA'!B6 -> 12 | L33: =BC!F109 -> 1920 | M33: =(L33/K33)*K33 -> 1920
C34: ALQUILER | L34: 570 | M34: =(L34*K33)/(12) -> 570
C35: EQUIPO | L35: 29260 | M35: =((((L34)*(K33))/'BIOMETRIA HEMATICA'!B2)) -> 0.56065574
A39: XNL-450 SIN LICENCIAS
A40: Parámetro | B40: ID | C40: PRODUCTO | D40: DET/KIT | E40: DIAS ESTABILIDAD | F40: DET/AÑO PROCESO | G40: PRODUCTO CALCULADO | H40: MINIMOS POR ESTABILIDAD | I40: PRODUCTO A ENTREGAR | K40: REDONDEADO A ENTREGAR | L40: PVP | M40: TOTAL | O40: PVP BIOMETRIA COMPLETA | P40: PARA PROCESO | Q40: VALOR INICIAL DEL PROCESO | R40: VALOR FINAL DEL PROCESO
A41: Biometria básica | B41: 6510167001 | C41: CELLPACK DCL | D41: 450 | E41: 60 | F41: ='BIOMETRIA HEMATICA'!$B$2 -> 12200 | G41: =F41/D41 -> 27.111111 | H41: =(360/E41)*'BIOMETRIA HEMATICA'!$B$10 -> 6 | I41: =IF(G41>H41,G41,H41) -> 27.111111 | K41: =ROUNDUP(I41,0) -> 28 | L41: 121 | M41: =L41*K41 -> 3388 | O41: =(SUM(M41:M50)/'BIOMETRIA HEMATICA'!B2)+M54 -> 1.4866352 | P41: =((O41*0.15)+O41) -> 1.7096305 | Q41: =P41*'BIOMETRIA HEMATICA'!B40 -> 0 | R41: =O41*'BIOMETRIA HEMATICA'!B40 -> 0
B42: 3337006001 | C42: SULFOLYSER REAGENT X 5L | D42: 9450 | E42: 60 | F42: ='BIOMETRIA HEMATICA'!$B$2 -> 12200 | G42: =F42/D42 -> 1.2910053 | H42: =(360/E42)*'BIOMETRIA HEMATICA'!$B$10 -> 6 | I42: =IF(G42>H42,G42,H42) -> 6 | J42: =IF(N42>N43,0,I42) -> 6 | L42: 1107 | M42: =L42*K42 -> 0 | N42: =L42*K42 -> 0 | O42: PVP BIOMETRIA | P42: PARA PROCESO | Q42: VALOR INICIAL DEL PROCESO | R42: VALOR FINAL DEL PROCESO
B43: 12215616001 | C43: SULFOLYSER REAGENT 500 ml | D43: 850 | E43: 60 | F43: ='BIOMETRIA HEMATICA'!$B$2 -> 12200 | G43: =F43/D43 -> 14.352941 | H43: =(360/E43)*'BIOMETRIA HEMATICA'!$B$10 -> 6 | I43: =IF(G43>H43,G43,H43) -> 14.352941 | J43: =IF(N43>N42,0,I43) -> 0 | K43: =ROUNDUP(I43,0) -> 15 | L43: 228.33 | M43: =L43*K43 -> 3424.95 | N43: =L43*K43 -> 3424.95 | O43: =(SUM(M41:M47)/'BIOMETRIA HEMATICA'!B2)+M54 -> 1.4866352 | P43: =((O43*0.15)+O43) -> 1.7096305 | Q43: =P43*'BIOMETRIA HEMATICA'!B40 -> 0 | R43: =O43*'BIOMETRIA HEMATICA'!B40 -> 0
B44: 7837984001 | C44: WDF Lysercell WDF | D44: 2450 | E44: 90 | F44: ='BIOMETRIA HEMATICA'!$B$2 -> 12200 | G44: =F44/D44 -> 4.9795918 | H44: =(360/E44)*'BIOMETRIA HEMATICA'!$B$10 -> 4 | I44: =IF(G44>H44,G44,H44) -> 4.9795918 | K44: =ROUNDUP(I44,0) -> 5 | L44: 176 | M44: =L44*K44 -> 880
B45: 6510256001 | C45: WDF Fluorocell WDF 2X42 ML | D45: 3400 | E45: 180 | F45: ='BIOMETRIA HEMATICA'!$B$2 -> 12200 | G45: =F45/D45 -> 3.5882353 | H45: =(360/E45)*'BIOMETRIA HEMATICA'!$B$10 -> 2 | I45: =IF(G45>H45,G45,H45) -> 3.5882353 | K45: =ROUNDUP(I45,0) -> 4 | L45: 862 | M45: =L45*K45 -> 3448
B46: 6952291001 | C46: CELLCLEAN AUTO 4 ML X 20 | D46: =(((F41/30)/12)*E46) -> 5083.3333 | E46: 150 | F46: ='BIOMETRIA HEMATICA'!$B$2 -> 12200 | G46: =F46/D46 -> 2.4 | H46: =(360/E46)*'BIOMETRIA HEMATICA'!$B$10 -> 2.4 | I46: =IF(G46>H46,G46,H46) -> 2.4 | K46: =ROUNDUP(I46,0) -> 3 | L46: 52 | M46: =L46*K46 -> 156
B47: 7051506001 | C47: XN Check 12x3.0ml Level 1,2,3 | D47: =(((F41/30)/12)*E47) -> 1897.7778 | E47: 56 | F47: ='BIOMETRIA HEMATICA'!$B$2 -> 12200 | G47: =F47/D47 -> 6.4285714 | H47: =(360/E47)*'BIOMETRIA HEMATICA'!$B$10 -> 6.4285714 | I47: =IF(G47>H47,G47,H47) -> 6.4285714 | L47: 544 | M47: =L47*K47 -> 0
A48: Reticulocitos | B48: 6510272001 | C48: FLUOROCELL RET 2 X 12ML | D48: 650 | E48: 180 | F48: ='BIOMETRIA HEMATICA'!$D$2 -> 0 | G48: =F48/D48 -> 0 | H48: =(360/E48)*'BIOMETRIA HEMATICA'!$B$10 -> 2 | I48: =IF(G48>H48,G48,H48) -> 2 | J48: =IF(G48=0,0,G48) -> 0 | L48: 1705 | M48: =L48*K48 -> 0
...

Sheet PRUEBA EFECTIVA XN
A1: XNL-350 SIN LICENCIAS
A2: Parámetro | B2: ID | C2: PRODUCTO | D2: DET/KIT | E2: DIAS ESTABILIDAD | F2: DET/AÑO PROCESO | G2: PRODUCTO CALCULADO | H2: MINIMOS POR ESTABILIDAD | I2: PRODUCTO A ENTREGAR | K2: REDONDEADO A ENTREGAR | L2: PVP | M2: TOTAL | O2: PVP BIOMETRIA COMPLETA | P2: PARA PROCESO | Q2: VALOR INICIAL DEL PROCESO | R2: VALOR FINAL DEL PROCESO
A3: Biometria básica | B3: 6510167001 | C3: CELLPACK DCL | D3: 450 | E3: 60 | F3: =(('BIOMETRIA HEMATICA'!$B$2)*0.2)+('BIOMETRIA HEMATICA'!$B$2) -> 14640 | G3: =F3/D3 -> 32.533333 | H3: =(360/E3)*'BIOMETRIA HEMATICA'!$B$10 -> 6 | I3: =IF(G3>H3,G3,H3) -> 32.533333 | K3: =ROUNDUP(I3,0) -> 33 | L3: 121 | M3: =L3*K3 -> 3993 | O3: =(SUM(M3:N12)/'BIOMETRIA HEMATICA'!B2)+M16 -> 3.9924492 | P3: =((O3*0.15)+O3) -> 4.5913166 | Q3: =P3*'BIOMETRIA HEMATICA'!B2 -> 56014.062 | R3: =O3*'BIOMETRIA HEMATICA'!B2 -> 48707.88
B4: 3337006001 | C4: SULFOLYSER REAGENT X 5L | D4: 9450 | E4: 60 | F4: =(('BIOMETRIA HEMATICA'!$B$2)*0.2)+('BIOMETRIA HEMATICA'!$B$2) -> 14640 | G4: =F4/D4 -> 1.5492063 | H4: =(360/E4)*'BIOMETRIA HEMATICA'!$B$10 -> 6 | I4: =IF(G4>H4,G4,H4) -> 6 | J4: =IF(N4>N5,0,I4) -> 0 | K4: =ROUNDUP(I4,0) -> 6 | L4: 1107 | M4: =L4*K4 -> 6642 | N4: =L4*K4 -> 6642 | O4: PVP BIOMETRIA | P4: PARA PROCESO | Q4: VALOR INICIAL DEL PROCESO | R4: VALOR FINAL DEL PROCESO
B5: 12215616001 | C5: SULFOLYSER REAGENT 500 ml | D5: 850 | E5: 60 | F5: =(('BIOMETRIA HEMATICA'!$B$2)*0.2)+('BIOMETRIA HEMATICA'!$B$2) -> 14640 | G5: =F5/D5 -> 17.223529 | H5: =(360/E5)*'BIOMETRIA HEMATICA'!$B$10 -> 6 | I5: =IF(G5>H5,G5,H5) -> 17.223529 | J5: =IF(N5>N4,0,I5) -> 17.223529 | K5: =ROUNDUP(I5,0) -> 18 | L5: 228.33 | M5: =L5*K5 -> 4109.94 | N5: =L5*K5 -> 4109.94 | O5: =(SUM(M3:N9)/'BIOMETRIA HEMATICA'!B2)+M16 -> 3.3169574 | P5: =((O5*0.15)+O5) -> 3.814501 | Q5: =P5*'BIOMETRIA HEMATICA'!B2 -> 46536.912 | R5: =O5*'BIOMETRIA HEMATICA'!B2 -> 40466.88
B6: 7837984001 | C6: WDF Lysercell WDF | D6: 2450 | E6: 90 | F6: =(('BIOMETRIA HEMATICA'!$B$2)*0.2)+('BIOMETRIA HEMATICA'!$B$2) -> 14640 | G6: =F6/D6 -> 5.9755102 | H6: =(360/E6)*'BIOMETRIA HEMATICA'!$B$10 -> 4 | I6: =IF(G6>H6,G6,H6) -> 5.9755102 | K6: =ROUNDUP(I6,0) -> 6 | L6: 176 | M6: =L6*K6 -> 1056
B7: 6510256001 | C7: WDF Fluorocell WDF 2X42 ML | D7: 3400 | E7: 180 | F7: =(('BIOMETRIA HEMATICA'!$B$2)*0.2)+('BIOMETRIA HEMATICA'!$B$2) -> 14640 | G7: =F7/D7 -> 4.3058824 | H7: =(360/E7)*'BIOMETRIA HEMATICA'!$B$10 -> 2 | I7: =IF(G7>H7,G7,H7) -> 4.3058824 | K7: =ROUNDUP(I7,0) -> 5 | L7: 862 | M7: =L7*K7 -> 4310
B8: 6952291001 | C8: CELLCLEAN AUTO 4 ML X 20 | D8: =(((F3/30)/12)*E8) -> 6100 | E8: 150 | F8: =(('BIOMETRIA HEMATICA'!$B$2)*0.2)+('BIOMETRIA HEMATICA'!$B$2) -> 14640 | G8: =F8/D8 -> 2.4 | H8: =(360/E8)*'BIOMETRIA HEMATICA'!$B$10 -> 2.4 | I8: =IF(G8>H8,G8,H8) -> 2.4 | K8: =ROUNDUP(I8,0) -> 3 | L8: 52 | M8: =L8*K8 -> 156
B9: 7051506001 | C9: XN Check 12x3.0ml Level 1,2,3 | D9: =(((F3/30)/12)*E9) -> 2277.3333 | E9: 56 | F9: =(('BIOMETRIA HEMATICA'!$B$2)*0.2)+('BIOMETRIA HEMATICA'!$B$2) -> 14640 | G9: =F9/D9 -> 6.4285714 | H9: =(360/E9)*'BIOMETRIA HEMATICA'!$B$10 -> 6.4285714 | I9: =IF(G9>H9,G9,H9) -> 6.4285714 | K9: =ROUNDUP(I9,0) -> 7 | L9: 544 | M9: =L9*K9 -> 3808
A10: Reticulocitos | B10: 6510272001 | C10: FLUOROCELL RET 2 X 12ML | D10: 650 | E10: 180 | F10: =(('BIOMETRIA HEMATICA'!$D$2)*0.2)+('BIOMETRIA HEMATICA'!$D$2) -> 0 | G10: =F10/D10 -> 0 | H10: =(360/E10)*'BIOMETRIA HEMATICA'!$B$10 -> 2 | I10: =IF(G10>H10,G10,H10) -> 2 | J10: =IF(G10=0,0,G10) -> 0 | K10: =ROUNDUP(I10,0) -> 2 | L10: 1705 | M10: =L10*K10 -> 3410
B11: 9426752001 | C11: CELLPACK DFL 1 L | D11: 450 | E11: 60 | F11: =(('BIOMETRIA HEMATICA'!$D$2)*0.2)+('BIOMETRIA HEMATICA'!$D$2) -> 0 | G11: =F11/D11 -> 0 | H11: =(360/E11)*'BIOMETRIA HEMATICA'!$B$10 -> 6 | I11: =IF(G11>H11,G11,H11) -> 6 | J11: =IF(G11=0,0,G11) -> 0 | K11: =ROUNDUP(I11,0) -> 6 | L11: 34 | M11: =L11*K11 -> 204
A12: Líquidos | B12: 7051409001 | C12: XN-Check BF 6x3.0ml Level 1,2 | D12: =(((F3/30)/12)*E12) -> 2277.3333 | E12: 56 | F12: =(('BIOMETRIA HEMATICA'!$H$2)*0.2)+('BIOMETRIA HEMATICA'!$H$2) -> 0 | G12: =F12/D12 -> 0 | H12: =(360/E12)*'BIOMETRIA HEMATICA'!$B$10 -> 6.4285714 | I12: =IF(G12>H12,G12,H12) -> 6.4285714 | J12: =IF(G12=0,0,G12) -> 0 | K12: =ROUNDUP(I12,0) -> 7 | L12: 661 | M12: =L12*K12 -> 4627
C14: ADICIONALES | K14: ='BIOMETRIA HEMATICA'!B6 -> 12 | L14: =BC!F109 -> 1920 | M14: =(L14/K14)*K14 -> 1920
C15: ALQUILER | L15: 470 | M15: =(L15*K14)/(12) -> 470
C16: EQUIPO | L16: 21362 | M16: =((((L15)*(K14))/'BIOMETRIA HEMATICA'!B2)) -> 0.46229508
A20: XNL-350 CON LICENCIAS
A21: Parámetro | B21: ID | C21: PRODUCTO | D21: DET/KIT | E21: DIAS ESTABILIDAD | F21: DET/AÑO PROCESO | G21: PRODUCTO CALCULADO | H21: MINIMOS POR ESTABILIDAD | I21: PRODUCTO A ENTREGAR | K21: REDONDEADO A ENTREGAR | L21: PVP | M21: TOTAL | O21: PVP BIOMETRIA | P21: PARA PROCESO | Q21: VALOR INICIAL DEL PROCESO | R21: VALOR FINAL DEL PROCESO
A22: Biometria básica | B22: 6510167001 | C22: CELLPACK DCL | D22: 450 | E22: 60 | F22: =(('BIOMETRIA HEMATICA'!$B$2)*0.2)+('BIOMETRIA HEMATICA'!$B$2) -> 14640 | G22: =F22/D22 -> 32.533333 | H22: =(360/E22)*'BIOMETRIA HEMATICA'!$B$10 -> 6 | I22: =IF(G22>H22,G22,H22) -> 32.533333 | K22: =ROUNDUP(I22,0) -> 33 | L22: 121 | M22: =L22*K22 -> 3993 | O22: =(SUM(M22:M34)/'BIOMETRIA HEMATICA'!B2)+M35 -> 3.4136016 | P22: =((O22*0.15)+O22) -> 3.9256419 | Q22: =P22*'BIOMETRIA HEMATICA'!B2 -> 47892.831 | R22: =O22*'BIOMETRIA HEMATICA'!B2 -> 41645.94
B23: 3337006001 | C23: SULFOLYSER REAGENT X 5L | D23: 9450 | E23: 60 | F23: =(('BIOMETRIA HEMATICA'!$B$2)*0.2)+('BIOMETRIA HEMATICA'!$B$2) -> 14640 | G23: =F23/D23 -> 1.5492063 | H23: =(360/E23)*'BIOMETRIA HEMATICA'!$B$10 -> 6 | I23: =IF(G23>H23,G23,H23) -> 6 | J23: =IF(N23>N24,0,I23) -> 0 | K23: =ROUNDUP(I23,0) -> 6 | L23: 1107 | M23: =L23*K23 -> 6642 | N23: =L23*K23 -> 6642
B24: 12215616001 | C24: SULFOLYSER REAGENT 500 ml | D24: 850 | E24: 60 | F24: =(('BIOMETRIA HEMATICA'!$B$2)*0.2)+('BIOMETRIA HEMATICA'!$B$2) -> 14640 | G24: =F24/D24 -> 17.223529 | H24: =(360/E24)*'BIOMETRIA HEMATICA'!$B$10 -> 6 | I24: =IF(G24>H24,G24,H24) -> 17.223529 | J24: =IF(N24>N23,0,I24) -> 17.223529 | K24: =ROUNDUP(I24,0) -> 18 | L24: 228.33 | M24: =L24*K24 -> 4109.94 | N24: =L24*K24 -> 4109.94
B25: 7837984001 | C25: WDF Lysercell WDF | D25: 2450 | E25: 90 | F25: =(('BIOMETRIA HEMATICA'!$B$2)*0.2)+('BIOMETRIA HEMATICA'!$B$2) -> 14640 | G25: =F25/D25 -> 5.9755102 | H25: =(360/E25)*'BIOMETRIA HEMATICA'!$B$10 -> 4 | I25: =IF(G25>H25,G25,H25) -> 5.9755102 | K25: =ROUNDUP(I25,0) -> 6 | L25: 176 | M25: =L25*K25 -> 1056
B26: 6510256001 | C26: WDF Fluorocell WDF 2X42 ML | D26: 3400 | E26: 180 | F26: =(('BIOMETRIA HEMATICA'!$B$2)*0.2)+('BIOMETRIA HEMATICA'!$B$2) -> 14640 | G26: =F26/D26 -> 4.3058824 | H26: =(360/E26)*'BIOMETRIA HEMATICA'!$B$10 -> 2 | I26: =IF(G26>H26,G26,H26) -> 4.3058824 | K26: =ROUNDUP(I26,0) -> 5 | L26: 862 | M26: =L26*K26 -> 4310
B27: 6952291001 | C27: CELLCLEAN AUTO 4 ML X 20 | D27: =(((F22/30)/12)*E27) -> 6100 | E27: 150 | F27: =(('BIOMETRIA HEMATICA'!$B$2)*0.2)+('BIOMETRIA HEMATICA'!$B$2) -> 14640 | G27: =F27/D27 -> 2.4 | H27: =(360/E27)*'BIOMETRIA HEMATICA'!$B$10 -> 2.4 | I27: =IF(G27>H27,G27,H27) -> 2.4 | K27: =ROUNDUP(I27,0) -> 3 | L27: 52 | M27: =L27*K27 -> 156
B28: 7051506001 | C28: XN Check 12x3.0ml Level 1,2,3 | D28: =(((F22/30)/12)*E28) -> 2277.3333 | E28: 56 | F28: =(('BIOMETRIA HEMATICA'!$B$2)*0.2)+('BIOMETRIA HEMATICA'!$B$2) -> 14640 | G28: =F28/D28 -> 6.4285714 | H28: =(360/E28)*'BIOMETRIA HEMATICA'!$B$10 -> 6.4285714 | I28: =IF(G28>H28,G28,H28) -> 6.4285714 | K28: =ROUNDUP(I28,0) -> 7 | L28: 544 | M28: =L28*K28 -> 3808
A29: Reticulocitos | B29: 6510272001 | C29: FLUOROCELL RET 2 X 12ML | D29: 650 | E29: 180 | F29: =(('BIOMETRIA HEMATICA'!$D$2)*0.2)+('BIOMETRIA HEMATICA'!$D$2) -> 0 | G29: =F29/D29 -> 0 | H29: =(360/E29)*'BIOMETRIA HEMATICA'!$B$10 -> 2 | I29: =IF(G29>H29,G29,H29) -> 2 | J29: =IF(G29=0,0,G29) -> 0 | K29: =ROUNDUP(I29,0) -> 2 | L29: 1705 | M29: =L29*K29 -> 3410
B30: 9426752001 | C30: CELLPACK DFL 1 L | D30: 450 | E30: 60 | F30: =(('BIOMETRIA HEMATICA'!$D$2)*0.2)+('BIOMETRIA HEMATICA'!$D$2) -> 0 | G30: =F30/D30 -> 0 | H30: =(360/E30)*'BIOMETRIA HEMATICA'!$B$10 -> 6 | I30: =IF(G30>H30,G30,H30) -> 6 | J30: =IF(G30=0,0,G30) -> 0 | K30: =ROUNDUP(I30,0) -> 6 | L30: 34 | M30: =L30*K30 -> 204
A31: Líquidos | B31: 7051409001 | C31: XN-Check BF 6x3.0ml Level 1,2 | D31: =(((F22/30)/12)*E31) -> 2277.3333 | E31: 56 | F31: =(('BIOMETRIA HEMATICA'!$H$2)*0.2)+('BIOMETRIA HEMATICA'!$H$2) -> 0 | G31: =F31/D31 -> 0 | H31: =(360/E31)*'BIOMETRIA HEMATICA'!$B$10 -> 6.4285714 | I31: =IF(G31>H31,G31,H31) -> 6.4285714 | J31: =IF(G10=0,0,G31) -> 0 | K31: =ROUNDUP(I31,0) -> 7 | L31: 661 | M31: =L31*K31 -> 4627
C33: ADICIONALES | K33: ='BIOMETRIA HEMATICA'!B6 -> 12 | L33: =BC!F109 -> 1920 | M33: =(L33/K33)*K33 -> 1920
C34: MANTENIMIENTO/REPUESTOS | L34: 570 | M34: =(L34*K33)/(12) -> 570
C35: EQUIPO | L35: 29260 | M35: =((((L34)*(K33))/'BIOMETRIA HEMATICA'!B2)) -> 0.56065574
A39: XNL-450 SIN LICENCIAS
A40: Parámetro | B40: ID | C40: PRODUCTO | D40: DET/KIT | E40: DIAS ESTABILIDAD | F40: DET/AÑO PROCESO | G40: PRODUCTO CALCULADO | H40: MINIMOS POR ESTABILIDAD | I40: PRODUCTO A ENTREGAR | K40: REDONDEADO A ENTREGAR | L40: PVP | M40: TOTAL | O40: PVP BIOMETRIA COMPLETA | P40: PARA PROCESO | Q40: VALOR INICIAL DEL PROCESO | R40: VALOR FINAL DEL PROCESO
A41: Biometria básica | B41: 6510167001 | C41: CELLPACK DCL | D41: 450 | E41: 60 | F41: =(('BIOMETRIA HEMATICA'!$B$2)*0.2)+('BIOMETRIA HEMATICA'!$B$2) -> 14640 | G41: =F41/D41 -> 32.533333 | H41: =(360/E41)*'BIOMETRIA HEMATICA'!$B$10 -> 6 | I41: =IF(G41>H41,G41,H41) -> 32.533333 | K41: =ROUNDUP(I41,0) -> 33 | L41: 121 | M41: =L41*K41 -> 3993 | O41: =(SUM(M41:M50)/'BIOMETRIA HEMATICA'!B2)+M54 -> 3.2095033 | P41: =((O41*0.15)+O41) -> 3.6909288 | Q41: =P41*'BIOMETRIA HEMATICA'!B40 -> 0 | R41: =O41*'BIOMETRIA HEMATICA'!B40 -> 0
B42: 3337006001 | C42: SULFOLYSER REAGENT X 5L | D42: 9450 | E42: 60 | F42: =(('BIOMETRIA HEMATICA'!$B$2)*0.2)+('BIOMETRIA HEMATICA'!$B$2) -> 14640 | G42: =F42/D42 -> 1.5492063 | H42: =(360/E42)*'BIOMETRIA HEMATICA'!$B$10 -> 6 | I42: =IF(G42>H42,G42,H42) -> 6 | J42: =IF(N42>N43,0,I42) -> 0 | K42: =ROUNDUP(I42,0) -> 6 | L42: 1107 | M42: =L42*K42 -> 6642 | N42: =L42*K42 -> 6642 | O42: PVP BIOMETRIA | P42: PARA PROCESO | Q42: VALOR INICIAL DEL PROCESO | R42: VALOR FINAL DEL PROCESO
B43: 12215616001 | C43: SULFOLYSER REAGENT 500 ml | D43: 850 | E43: 60 | F43: =(('BIOMETRIA HEMATICA'!$B$2)*0.2)+('BIOMETRIA HEMATICA'!$B$2) -> 14640 | G43: =F43/D43 -> 17.223529 | H43: =(360/E43)*'BIOMETRIA HEMATICA'!$B$10 -> 6 | I43: =IF(G43>H43,G43,H43) -> 17.223529 | J43: =IF(N43>N42,0,I43) -> 17.223529 | K43: =ROUNDUP(I43,0) -> 18 | L43: 228.33 | M43: =L43*K43 -> 4109.94 | N43: =L43*K43 -> 4109.94 | O43: =(SUM(M41:M47)/'BIOMETRIA HEMATICA'!B2)+M54 -> 2.5340115 | P43: =((O43*0.15)+O43) -> 2.9141132 | Q43: =P43*'BIOMETRIA HEMATICA'!B40 -> 0 | R43: =O43*'BIOMETRIA HEMATICA'!B40 -> 0
B44: 7837984001 | C44: WDF Lysercell WDF | D44: 2450 | E44: 90 | F44: =(('BIOMETRIA HEMATICA'!$B$2)*0.2)+('BIOMETRIA HEMATICA'!$B$2) -> 14640 | G44: =F44/D44 -> 5.9755102 | H44: =(360/E44)*'BIOMETRIA HEMATICA'!$B$10 -> 4 | I44: =IF(G44>H44,G44,H44) -> 5.9755102 | K44: =ROUNDUP(I44,0) -> 6 | L44: 176 | M44: =L44*K44 -> 1056
B45: 6510256001 | C45: WDF Fluorocell WDF 2X42 ML | D45: 3400 | E45: 180 | F45: =(('BIOMETRIA HEMATICA'!$B$2)*0.2)+('BIOMETRIA HEMATICA'!$B$2) -> 14640 | G45: =F45/D45 -> 4.3058824 | H45: =(360/E45)*'BIOMETRIA HEMATICA'!$B$10 -> 2 | I45: =IF(G45>H45,G45,H45) -> 4.3058824 | K45: =ROUNDUP(I45,0) -> 5 | L45: 862 | M45: =L45*K45 -> 4310
B46: 6952291001 | C46: CELLCLEAN AUTO 4 ML X 20 | D46: =(((F41/30)/12)*E46) -> 6100 | E46: 150 | F46: =(('BIOMETRIA HEMATICA'!$B$2)*0.2)+('BIOMETRIA HEMATICA'!$B$2) -> 14640 | G46: =F46/D46 -> 2.4 | H46: =(360/E46)*'BIOMETRIA HEMATICA'!$B$10 -> 2.4 | I46: =IF(G46>H46,G46,H46) -> 2.4 | K46: =ROUNDUP(I46,0) -> 3 | L46: 52 | M46: =L46*K46 -> 156
B47: 7051506001 | C47: XN Check 12x3.0ml Level 1,2,3 | D47: =(((F41/30)/12)*E47) -> 2277.3333 | E47: 56 | F47: =(('BIOMETRIA HEMATICA'!$B$2)*0.2)+('BIOMETRIA HEMATICA'!$B$2) -> 14640 | G47: =F47/D47 -> 6.4285714 | H47: =(360/E47)*'BIOMETRIA HEMATICA'!$B$10 -> 6.4285714 | I47: =IF(G47>H47,G47,H47) -> 6.4285714 | K47: =ROUNDUP(I47,0) -> 7 | L47: 544 | M47: =L47*K47 -> 3808
A48: Reticulocitos | B48: 6510272001 | C48: FLUOROCELL RET 2 X 12ML | D48: 650 | E48: 180 | F48: =(('BIOMETRIA HEMATICA'!$D$2)*0.2)+('BIOMETRIA HEMATICA'!$D$2) -> 0 | G48: =F48/D48 -> 0 | H48: =(360/E48)*'BIOMETRIA HEMATICA'!$B$10 -> 2 | I48: =IF(G48>H48,G48,H48) -> 2 | J48: =IF(G48=0,0,G48) -> 0 | K48: =ROUNDUP(I48,0) -> 2 | L48: 1705 | M48: =L48*K48 -> 3410
...

Sheet COMODATO TODO COMPRADO XN
A1: XNL-350 SIN LICENCIAS
A2: Parámetro | B2: ID | C2: PRODUCTO | D2: DET/KIT | E2: DIAS ESTABILIDAD | F2: DET/AÑO PROCESO | G2: PRODUCTO CALCULADO | H2: MINIMOS POR ESTABILIDAD | I2: PRODUCTO A ENTREGAR | K2: REDONDEADO A ENTREGAR | L2: PVP | M2: TOTAL | O2: PVP TODO COMPRADO | P2: TOTAL TODO COMPRADO | Q2: PVP BIOMETRIA COMPLETA
A3: Biometria básica | B3: 6510167001 | C3: CELLPACK DCL | D3: 450 | E3: 60 | F3: =(('BIOMETRIA HEMATICA'!$B$2)) -> 12200 | G3: =F3/D3 -> 27.111111 | H3: =(360/E3)*'BIOMETRIA HEMATICA'!$B$10 -> 6 | I3: =IF(G3>H3,G3,H3) -> 27.111111 | K3: =ROUNDDOWN(I3,0) -> 27 | L3: 121 | M3: =L3*K3 -> 3267 | O3: =(L3*$L$19)+L3 -> 522.45087 | P3: =O3*K3 -> 14106.173 | Q3: =(SUM(P3:P12)/'BIOMETRIA HEMATICA'!B2)+M16 -> 10.139641
B4: 3337006001 | C4: SULFOLYSER REAGENT X 5L | D4: 9450 | E4: 60 | F4: =(('BIOMETRIA HEMATICA'!$B$2)) -> 12200 | G4: =F4/D4 -> 1.2910053 | H4: =(360/E4)*'BIOMETRIA HEMATICA'!$B$10 -> 6 | I4: =IF(G4>H4,G4,H4) -> 6 | J4: =IF(N4>N5,0,I4) -> 0 | K4: =ROUNDDOWN(I4,0) -> 6 | L4: 1107 | M4: =L4*K4 -> 6642 | N4: =L4*K4 -> 6642 | O4: =(L4*$L$19)+L4 -> 4779.7778 | P4: =O4*K4 -> 28678.667 | Q4: PVP BIOMETRIA
B5: 12215616001 | C5: SULFOLYSER REAGENT 500 ml | D5: 850 | E5: 60 | F5: =(('BIOMETRIA HEMATICA'!$B$2)) -> 12200 | G5: =F5/D5 -> 14.352941 | H5: =(360/E5)*'BIOMETRIA HEMATICA'!$B$10 -> 6 | I5: =IF(G5>H5,G5,H5) -> 14.352941 | J5: =IF(N5>N4,0,I5) -> 14.352941 | K5: =ROUNDDOWN(I5,0) -> 14 | L5: 228.33 | M5: =L5*K5 -> 3196.62 | N5: =L5*K5 -> 3196.62 | O5: =(L5*$L$19)+L5 -> 985.87774 | P5: =O5*K5 -> 13802.288 | Q5: =(SUM(P3:P9)/'BIOMETRIA HEMATICA'!B2)+M16 -> 7.4569573
B6: 7837984001 | C6: WDF Lysercell WDF | D6: 2450 | E6: 90 | F6: =(('BIOMETRIA HEMATICA'!$B$2)) -> 12200 | G6: =F6/D6 -> 4.9795918 | H6: =(360/E6)*'BIOMETRIA HEMATICA'!$B$10 -> 4 | I6: =IF(G6>H6,G6,H6) -> 4.9795918 | K6: =ROUNDDOWN(I6,0) -> 4 | L6: 176 | M6: =L6*K6 -> 704 | O6: =(L6*$L$19)+L6 -> 759.92854 | P6: =O6*K6 -> 3039.7141
B7: 6510256001 | C7: WDF Fluorocell WDF 2X42 ML | D7: 3400 | E7: 180 | F7: =(('BIOMETRIA HEMATICA'!$B$2)) -> 12200 | G7: =F7/D7 -> 3.5882353 | H7: =(360/E7)*'BIOMETRIA HEMATICA'!$B$10 -> 2 | I7: =IF(G7>H7,G7,H7) -> 3.5882353 | K7: =ROUNDDOWN(I7,0) -> 3 | L7: 862 | M7: =L7*K7 -> 2586 | O7: =(L7*$L$19)+L7 -> 3721.9227 | P7: =O7*K7 -> 11165.768
B8: 6952291001 | C8: CELLCLEAN AUTO 4 ML X 20 | D8: =(((F3/30)/12)*E8) -> 5083.3333 | E8: 150 | F8: =(('BIOMETRIA HEMATICA'!$B$2)) -> 12200 | G8: =F8/D8 -> 2.4 | H8: =(360/E8)*'BIOMETRIA HEMATICA'!$B$10 -> 2.4 | I8: =IF(G8>H8,G8,H8) -> 2.4 | K8: =ROUNDDOWN(I8,0) -> 2 | L8: 52 | M8: =L8*K8 -> 104 | O8: =(L8*$L$19)+L8 -> 224.52434 | P8: =O8*K8 -> 449.04868
B9: 7051506001 | C9: XN Check 12x3.0ml Level 1,2,3 | D9: =(((F3/30)/12)*E9) -> 1897.7778 | E9: 56 | F9: =(('BIOMETRIA HEMATICA'!$B$2)) -> 12200 | G9: =F9/D9 -> 6.4285714 | H9: =(360/E9)*'BIOMETRIA HEMATICA'!$B$10 -> 6.4285714 | I9: =IF(G9>H9,G9,H9) -> 6.4285714 | K9: =ROUNDDOWN(I9,0) -> 6 | L9: 544 | M9: =L9*K9 -> 3264 | O9: =(L9*$L$19)+L9 -> 2348.87 | P9: =O9*K9 -> 14093.22
A10: Reticulocitos | B10: 6510272001 | C10: FLUOROCELL RET 2 X 12ML | D10: 650 | E10: 180 | F10: =(('BIOMETRIA HEMATICA'!$D$2)) -> 0 | G10: =F10/D10 -> 0 | H10: =(360/E10)*'BIOMETRIA HEMATICA'!$B$10 -> 2 | I10: =IF(G10>H10,G10,H10) -> 2 | J10: =IF(G10=0,0,G10) -> 0 | K10: =ROUNDDOWN(I10,0) -> 2 | L10: 1705 | M10: =L10*K10 -> 3410 | O10: =(L10*$L$19)+L10 -> 7361.8077 | P10: =O10*K10 -> 14723.615
B11: 9426752001 | C11: CELLPACK DFL 1 L | D11: 450 | E11: 60 | F11: =(('BIOMETRIA HEMATICA'!$D$2)) -> 0 | G11: =F11/D11 -> 0 | H11: =(360/E11)*'BIOMETRIA HEMATICA'!$B$10 -> 6 | I11: =IF(G11>H11,G11,H11) -> 6 | J11: =IF(G11=0,0,G11) -> 0 | K11: =ROUNDDOWN(I11,0) -> 6 | L11: 34 | M11: =L11*K11 -> 204 | O11: =(L11*$L$19)+L11 -> 146.80438 | P11: =O11*K11 -> 880.82626
A12: Líquidos | B12: 7051409001 | C12: XN-Check BF 6x3.0ml Level 1,2 | D12: =(((F3/30)/12)*E12) -> 1897.7778 | E12: 56 | F12: =(('BIOMETRIA HEMATICA'!$H$2)) -> 0 | G12: =F12/D12 -> 0 | H12: =(360/E12)*'BIOMETRIA HEMATICA'!$B$10 -> 6.4285714 | I12: =IF(G12>H12,G12,H12) -> 6.4285714 | J12: =IF(G12=0,0,G12) -> 0 | K12: =ROUNDDOWN(I12,0) -> 6 | L12: 661 | M12: =L12*K12 -> 3966 | O12: =(L12*$L$19)+L12 -> 2854.0498 | P12: =O12*K12 -> 17124.299
P13: =SUM(P3:P12) -> 118063.62
C14: ADICIONALES | K14: ='BIOMETRIA HEMATICA'!B6 -> 12 | L14: =BC!F109 -> 1920 | M14: =(L14/K14)*K14 -> 1920
C15: MANTENIMIENTO/REPUESTOS | L15: 470 | M15: =(L15*K14) -> 5640
C16: EQUIPO | L16: 21362 | M16: =((((L15)*(K14))/'BIOMETRIA HEMATICA'!B2)) -> 0.46229508
L17: =SUM(M14:M15) -> 7560 | P17: =P13-L18 -> 90720
L18: =SUM(M3:M12) -> 27343.62 | P18: =L15*K14 -> 5640
L19: =(L17/L18)*K14 -> 3.3177758
A24: XNL-350 CON LICENCIAS
A25: Parámetro | B25: ID | C25: PRODUCTO | D25: DET/KIT | E25: DIAS ESTABILIDAD | F25: DET/AÑO PROCESO | G25: PRODUCTO CALCULADO | H25: MINIMOS POR ESTABILIDAD | I25: PRODUCTO A ENTREGAR | K25: REDONDEADO A ENTREGAR | L25: PVP | M25: TOTAL | O25: PVP TODO COMPRADO | P25: TOTAL TODO COMPRADO | Q25: PVP BIOMETRIA COMPLETA
A26: Biometria básica | B26: 6510167001 | C26: CELLPACK DCL | D26: 450 | E26: 60 | F26: =(('BIOMETRIA HEMATICA'!$B$2)) -> 12200 | G26: =F26/D26 -> 27.111111 | H26: =(360/E26)*'BIOMETRIA HEMATICA'!$B$10 -> 6 | I26: =IF(G26>H26,G26,H26) -> 27.111111 | K26: =ROUNDDOWN(I26,0) -> 27 | L26: 121 | M26: =L26*K26 -> 3267 | O26: =(L26*$L$42)+L26 -> 586.17323 | P26: =O26*K26 -> 15826.677 | Q26: =(SUM(P26:P35)/'BIOMETRIA HEMATICA'!B2)+M39 -> 11.41833
B27: 3337006001 | C27: SULFOLYSER REAGENT X 5L | D27: 9450 | E27: 60 | F27: =(('BIOMETRIA HEMATICA'!$B$2)) -> 12200 | G27: =F27/D27 -> 1.2910053 | H27: =(360/E27)*'BIOMETRIA HEMATICA'!$B$10 -> 6 | I27: =IF(G27>H27,G27,H27) -> 6 | J27: =IF(N27>N28,0,I27) -> 0 | K27: =ROUNDDOWN(I27,0) -> 6 | L27: 1107 | M27: =L27*K27 -> 6642 | N27: =L27*K27 -> 6642 | O27: =(L27*$L$42)+L27 -> 5362.7584 | P27: =O27*K27 -> 32176.55 | Q27: PVP BIOMETRIA
B28: 12215616001 | C28: SULFOLYSER REAGENT 500 ml | D28: 850 | E28: 60 | F28: =(('BIOMETRIA HEMATICA'!$B$2)) -> 12200 | G28: =F28/D28 -> 14.352941 | H28: =(360/E28)*'BIOMETRIA HEMATICA'!$B$10 -> 6 | I28: =IF(G28>H28,G28,H28) -> 14.352941 | J28: =IF(N28>N27,0,I28) -> 14.352941 | K28: =ROUNDDOWN(I28,0) -> 14 | L28: 228.33 | M28: =L28*K28 -> 3196.62 | N28: =L28*K28 -> 3196.62 | O28: =(L28*$L$42)+L28 -> 1106.1234 | P28: =O28*K28 -> 15485.728 | Q28: =(SUM(P26:P32)/'BIOMETRIA HEMATICA'!B2)+M39 -> 8.4084439
B29: 7837984001 | C29: WDF Lysercell WDF | D29: 2450 | E29: 90 | F29: =(('BIOMETRIA HEMATICA'!$B$2)) -> 12200 | G29: =F29/D29 -> 4.9795918 | H29: =(360/E29)*'BIOMETRIA HEMATICA'!$B$10 -> 4 | I29: =IF(G29>H29,G29,H29) -> 4.9795918 | K29: =ROUNDDOWN(I29,0) -> 4 | L29: 176 | M29: =L29*K29 -> 704 | O29: =(L29*$L$42)+L29 -> 852.61561 | P29: =O29*K29 -> 3410.4624
B30: 6510256001 | C30: WDF Fluorocell WDF 2X42 ML | D30: 3400 | E30: 180 | F30: =(('BIOMETRIA HEMATICA'!$B$2)) -> 12200 | G30: =F30/D30 -> 3.5882353 | H30: =(360/E30)*'BIOMETRIA HEMATICA'!$B$10 -> 2 | I30: =IF(G30>H30,G30,H30) -> 3.5882353 | K30: =ROUNDDOWN(I30,0) -> 3 | L30: 862 | M30: =L30*K30 -> 2586 | O30: =(L30*$L$42)+L30 -> 4175.8787 | P30: =O30*K30 -> 12527.636
B31: 6952291001 | C31: CELLCLEAN AUTO 4 ML X 20 | D31: =(((F26/30)/12)*E31) -> 5083.3333 | E31: 150 | F31: =(('BIOMETRIA HEMATICA'!$B$2)) -> 12200 | G31: =F31/D31 -> 2.4 | H31: =(360/E31)*'BIOMETRIA HEMATICA'!$B$10 -> 2.4 | I31: =IF(G31>H31,G31,H31) -> 2.4 | K31: =ROUNDDOWN(I31,0) -> 2 | L31: 52 | M31: =L31*K31 -> 104 | O31: =(L31*$L$42)+L31 -> 251.90916 | P31: =O31*K31 -> 503.81831
B32: 7051506001 | C32: XN Check 12x3.0ml Level 1,2,3 | D32: =(((F26/30)/12)*E32) -> 1897.7778 | E32: 56 | F32: =(('BIOMETRIA HEMATICA'!$B$2)) -> 12200 | G32: =F32/D32 -> 6.4285714 | H32: =(360/E32)*'BIOMETRIA HEMATICA'!$B$10 -> 6.4285714 | I32: =IF(G32>H32,G32,H32) -> 6.4285714 | K32: =ROUNDDOWN(I32,0) -> 6 | L32: 544 | M32: =L32*K32 -> 3264 | O32: =(L32*$L$42)+L32 -> 2635.3573 | P32: =O32*K32 -> 15812.144
A33: Reticulocitos | B33: 6510272001 | C33: FLUOROCELL RET 2 X 12ML | D33: 650 | E33: 180 | F33: =(('BIOMETRIA HEMATICA'!$D$2)) -> 0 | G33: =F33/D33 -> 0 | H33: =(360/E33)*'BIOMETRIA HEMATICA'!$B$10 -> 2 | I33: =IF(G33>H33,G33,H33) -> 2 | J33: =IF(G33=0,0,G33) -> 0 | K33: =ROUNDDOWN(I33,0) -> 2 | L33: 1705 | M33: =L33*K33 -> 3410 | O33: =(L33*$L$42)+L33 -> 8259.7137 | P33: =O33*K33 -> 16519.427
B34: 9426752001 | C34: CELLPACK DFL 1 L | D34: 450 | E34: 60 | F34: =(('BIOMETRIA HEMATICA'!$D$2)) -> 0 | G34: =F34/D34 -> 0 | H34: =(360/E34)*'BIOMETRIA HEMATICA'!$B$10 -> 6 | I34: =IF(G34>H34,G34,H34) -> 6 | J34: =IF(G34=0,0,G34) -> 0 | K34: =ROUNDDOWN(I34,0) -> 6 | L34: 34 | M34: =L34*K34 -> 204 | O34: =(L34*$L$42)+L34 -> 164.70983 | P34: =O34*K34 -> 988.259
A35: Líquidos | B35: 7051409001 | C35: XN-Check BF 6x3.0ml Level 1,2 | D35: =(((F26/30)/12)*E35) -> 1897.7778 | E35: 56 | F35: =(('BIOMETRIA HEMATICA'!$H$2)) -> 0 | G35: =F35/D35 -> 0 | H35: =(360/E35)*'BIOMETRIA HEMATICA'!$B$10 -> 6.4285714 | I35: =IF(G35>H35,G35,H35) -> 6.4285714 | J35: =IF(G10=0,0,G35) -> 0 | K35: =ROUNDDOWN(I35,0) -> 6 | L35: 661 | M35: =L35*K35 -> 3966 | O35: =(L35*$L$42)+L35 -> 3202.1529 | P35: =O35*K35 -> 19212.918
P36: =SUM(P26:P35) -> 132463.62
C37: ADICIONALES | K37: ='BIOMETRIA HEMATICA'!B6 -> 12 | L37: =BC!F109 -> 1920 | M37: =(L37/K37)*K37 -> 1920
C38: MANTENIMIENTO/REPUESTOS | L38: 570 | M38: =(L38*K37) -> 6840
C39: EQUIPO | L39: 29260 | M39: =((((L38)*(K37))/'BIOMETRIA HEMATICA'!B2)) -> 0.56065574
L40: =SUM(M37:M38) -> 8760 | P40: =P36-L41 -> 105120
L41: =SUM(M26:M35) -> 27343.62 | P41: =L38*K37 -> 6840
L42: =(L40/L41)*K37 -> 3.8444068
A46: XNL-450 SIN LICENCIAS
A47: Parámetro | B47: ID | C47: PRODUCTO | D47: DET/KIT | E47: DIAS ESTABILIDAD | F47: DET/AÑO PROCESO | G47: PRODUCTO CALCULADO | H47: MINIMOS POR ESTABILIDAD | I47: PRODUCTO A ENTREGAR | K47: REDONDEADO A ENTREGAR | L47: PVP | M47: TOTAL | O47: PVP TODO COMPRADO | P47: TOTAL TODO COMPRADO | Q47: PVP BIOMETRIA COMPLETA
...
