Workbook

Sheet BC
A1: INFORMACIÓN GENERAL PARA CASO DE NEGOCIO (BC)
A2: Actualización: 08 enero 2026. 16:06
A3: FECHA MAXIMA PARA CALCULO DE CONSUMIBLES (NO MENOR A 48 HORAS)
A4: TIPO DE CLIENTE
A5: ENTIDAD CONTRATANTE
A6: CLIENTE
A7: Código del Proceso
A8: Objeto de contratación
A9: Provincia /Ciudad
A10: * Ambiente de Laboratorio :
A11: Número de días por semana que trabaja el laboratorio
A12: Turnos por dia
... A55: Observaciones
A57: *Inversiones adicionales | B57: Características | C57: Estado | D57: Cantidad | E57: Precio | F57: Total
A58: Control externo de tercera opinión | D58: 0 | F58: =E58*D58 -> 0
A59: Control interno interlaboratorial | D59: 0 | F59: =E59*D59 -> 0
A60: Póliza de Fiel Cumplimiento del Contrato | B60: 72126.03 | D60: 0 | F60: =E60*D60 -> 0
A61: Póliza de seguro de equipos | D61: 0 | F61: =E61*D61 -> 0
A62: Ups equipo | B62: Equipo | D62: 0 | F62: =E62*D62 -> 0
A63: Ups servidor | B63: Powest on line 1kva 1000VA | D63: 0 | E63: 200 | F63: =E63*D63 -> 0
A64: LIS | D64: 0 | F64: =E64*D64 -> 0
A65: Interfaz | D65: 0 | E65: 1500 | F65: =E65*D65 -> 0
A66: Lantronix | D66: 0 | F66: =E66*D66 -> 0
A67: IP publica | D67: 0 | F67: =E67*D67 -> 0
A68: Punto de consulta web | D68: 0 | F68: =E68*D68 -> 0
A69: Internet | D69: 0 | F69: =E69*D69 -> 0
A70: Router para Internet | D70: 0 | F70: =E70*D70 -> 0
A71: Servidor | D71: 0 | F71: =E71*D71 -> 0
A72: Computadores | B72: Monitor + Teclado y mouse | D72: 0 | E72: 900 | F72: =E72*D72 -> 0
A73: Mantenimiento Computador | F73: =E73*D73 -> 0
A74: Impresora | D74: 0 | E74: 300 | F74: =E74*D74 -> 0
A75: Mantenimiento Impresora | F75: =E75*D75 -> 0
A76: Tinta | D76: 0 | F76: =E76*D76 -> 0
A77: Toner para impresora de equipos (en caso de dejar las impresoras) | D77: 0 | E77: 200 | F77: =E77*D77 -> 0
A78: Impresora Zebra Termica ZD230 ETHERNET Y USB | D78: 0 | E78: 400 | F78: =E78*D78 -> 0
A79: Mantenimiento Impresora Zebra Termica ZD230 ETHERNET Y USB | F79: =E79*D79 -> 0
A80: Lector inalambrico de codigo de barra | D80: 0 | F80: =E80*D80 -> 0
A81: Sistema de destilación de agua pequeño | D81: 0 | F81: =E81*D81 -> 0
A82: Sistema de osmosis | D82: 0 | F82: =E82*D82 -> 0
A83: Mantenimiento sistema de osmosis | F83: =E83*D83 -> 0
...

Sheet c111
A1: CLIENTE
A2: FECHA
A3: MODALIDAD
A4: PLAZO | C4: MESES
A5: PROYECCIÓN | C5: MESES
A6: EQUIPO | B6: c 111
A8: ID | B8: REACTIVO | C8: DET/KIT | D8: DIAS ESTABILIDAD | E8: CANTIDAD PROCESO/AÑO | F8: PRODUCTO CALCULADO | G8: MINIMOS POR ESTABILIDAD | H8: PRODUCTO A ENTREGAR
A9: 4657527190 | B9: Glucosa | C9: 400 | D9: 120 | F9: =E9/C9 -> 0 | G9: =365/D9 -> 3.0416667
A10: 4657616190 | B10: Urea | C10: 400 | D10: 120 | F10: =E10/C10 -> 0 | G10: =365/D10 -> 3.0416667
A11: 5401755190 | B11: Creatinina | C11: 400 | D11: 120 | F11: =E11/C11 -> 0 | G11: =365/D11 -> 3.0416667
A12: 4657608190 | B12: Acido Úrico | C12: 400 | D12: 120 | F12: =E12/C12 -> 0 | G12: =365/D12 -> 3.0416667
A13: 4718917190 | B13: Colesterol | C13: 400 | D13: 120 | F13: =E13/C13 -> 0 | G13: =365/D13 -> 3.0416667
A14: 4657594190 | B14: Triglicéridos | C14: 200 | D14: 120 | F14: =E14/C14 -> 0 | G14: =365/D14 -> 3.0416667
A15: 4718569190 | B15: ALT - TGP | C15: 400 | D15: 120 | F15: =E15/C15 -> 0 | G15: =365/D15 -> 3.0416667
A16: 4657543190 | B16: AST - TGO | C16: 400 | D16: 120 | F16: =E16/C16 -> 0 | G16: =365/D16 -> 3.0416667
A17: 4657373190 | B17: Fosfatasa alcalina | C17: 200 | D17: 120 | F17: =E17/C17 -> 0 | G17: =365/D17 -> 3.0416667
A18: 5795648190 | B18: Bilirrubina Total | C18: 400 | D18: 120 | F18: =E18/C18 -> 0 | G18: =365/D18 -> 3.0416667
A19: 5589134190 | B19: Bilirrubina Directa | C19: 100 | D19: 60 | F19: =E19/C19 -> 0 | G19: =365/D19 -> 6.0833333
A20: 7528604190 | B20: HDL Colesterol | C20: 200 | D20: 60 | F20: =E20/C20 -> 0 | G20: =365/D20 -> 6.0833333
... A37: 7442050190 | B37: CK-MB | C37: 100 | D37: 60 | F37: =E37/C37 -> 0 | G37: =365/D37 -> 6.0833333
C38: TOTAL DET | E38: =SUM(E9:E37) -> 0
A39: CALIBRADOR
A40: 10759350190 | B40: Calibrator f.a.s. 12x3 ml | C40: 12 | D40: 28 | G40: =(365/D40)/C40 -> 1.0863095
A41: 12172623122 | B41: Cfas Lipids 3x1ML | C41: 3 | D41: 28 | G41: =(365/D41)/C41 -> 4.3452381
A42: 11355279216 | B42: Cfas Proteins | C42: 5 | D42: 28 | G42: =(365/D42)/C42 -> 2.6071429
A43: 4528417190 | B43: Cfas HbA1c, 3x2ml | C43: 3 | D43: 84 | G43: =(365/D43)/C43 -> 1.4484127
A44: 20751995190 | B44: Ammonia/Ethanol/CO2 Calibrator | C44: 2 | D44: 56 | G44: =(365/D44)/C44 -> 3.2589286
A45: 5050901190 | B45: Cfas D- Dimer | C45: 1 | D45: 84 | G45: =(365/D45)/C45 -> 4.3452381
A46: 11447394216 | B46: Calibrator f.a.s. CK‑MB | C46: 3 | D46: 28 | G46: =(365/D46)/C46 -> 4.3452381
A47: CONTROL
A48: 5947626190 | B48: PreciControl ClinChem Multi 1 4x5ml | C48: 4 | D48: 14 | G48: =(365/D48)/C48 -> 6.5178571
A49: 5947774190 | B49: PreciControl ClinChem Multi 2 4x5ml | C49: 4 | D49: 14 | G49: =(365/D49)/C49 -> 6.5178571
A50: 5479207190 | B50: PreciControl HBA1c Norm | C50: 4 | D50: 28 | G50: =(365/D50)/C50 -> 3.2589286
A51: 5912504190 | B51: PRECICONTROL HBA1C PATH | C51: 4 | D51: 28 | G51: =(365/D51)/C51 -> 3.2589286
A52: 20752401190 | B52: Ammonia/Ethanol/CO2 Control Normal | C52: 5 | D52: 56 | G52: =(365/D52)/C52 -> 1.3035714
A53: 20753009190 | B53: Ammonia/Ethanol/CO2 Control Normal | C53: 5 | D53: 56 | G53: =(365/D53)/C53 -> 1.3035714
A54: 5050936190 | B54: PreciControl D- Dimer | C54: 2 | D54: 84 | G54: =(365/D54)/C54 -> 2.172619
A55: CONSUMIBLES
A56: 4774230190 | B56: NaCL 9% cobas c 111 | C56: 4 | D56: 28 | G56: =(365/D56)/C56 -> 3.2589286
A57: 5007232190 | B57: HAEMOLYSE REAGENT 800T COBAS C111 | C57: 8 | D57: 10 | G57: =(365/D57)/C57 -> 4.5625
...

Sheet c111 DETERMIACION
B2: ID | C2: REACTIVO | D2: DET/KIT | E2: DIAS ESTABILIDAD | F2: CANTIDAD PROCESO/AÑO | G2: PRODUCTO CALCULADO | H2: MINIMOS POR ESTABILIDAD | I2: PRODUCTO A ENTREGAR | K2: REDONDEADO A ENTREGAR | L2: PVP | M2: TOTAL | N2: $ DETERMINACION | O2: $DETERMINACION CON CONSUMIBLES Y EXTRAS | P2: TOTAL CON CONSUMIBLES Y EXTRAS | Q2: $ PARA PROCESO | R2: TOTAL PARA PROCESO | S2: VALOR INICIAL DEL PROCESO | T2: VALOR FINAL DEL PROCESO
A3: cfas | B3: 4657527190 | C3: Glucosa | D3: 400 | E3: 120 | F3: ='c111'!E9 -> 0 | G3: =F3/D3 -> 0 | H3: =30*BC!$B$47/E3 -> 0 | I3: =IF(H3>G3,H3,G3) -> 0 | J3: =IF(G3=0,0,I3) -> 0 | K3: =ROUNDUP(J3,0) -> 0 | L3: 50 | M3: =L3*K3 -> 0 | N3: =L3/D3 -> 0.125 | O3: =N3+$N$62+((BC!$F$125)/'c111 DETERMIACION'!$F$32) -> #DIV/0! | P3: =O3*F3 -> #DIV/0! | Q3: =((O3*0.15)+O3) -> #DIV/0! | R3: =Q3*F3 -> #DIV/0! | S3: =SUM(R3:R31) -> #DIV/0! | T3: =SUM(P3:P31) -> #DIV/0!
A4: =SUM(F3+F4+F5+F6+F7+F8+F9+F10+F11+F12+F13+F15+F16+F17+F18+F20+F21+F22+F24+F25+F28+F30) -> 0 | B4: 4657616190 | C4: Urea | D4: 400 | E4: 120 | F4: ='c111'!E10 -> 0 | G4: =F4/D4 -> 0 | H4: =30*BC!$B$47/E4 -> 0 | I4: =IF(H4>G4,H4,G4) -> 0 | J4: =IF(G4=0,0,I4) -> 0 | K4: =ROUNDUP(J4,0) -> 0 | L4: 62 | M4: =L4*K4 -> 0 | N4: =L4/D4 -> 0.155 | O4: =N4+$N$62+((BC!$F$125)/'c111 DETERMIACION'!$F$32) -> #DIV/0! | P4: =O4*F4 -> #DIV/0! | Q4: =((O4*0.15)+O4) -> #DIV/0! | R4: =Q4*F4 -> #DIV/0!
B5: 5401755190 | C5: Creatinina | D5: 400 | E5: 120 | F5: ='c111'!E11 -> 0 | G5: =F5/D5 -> 0 | H5: =30*BC!$B$47/E5 -> 0 | I5: =IF(H5>G5,H5,G5) -> 0 | J5: =IF(G5=0,0,I5) -> 0 | K5: =ROUNDUP(J5,0) -> 0 | L5: 74 | M5: =L5*K5 -> 0 | N5: =L5/D5 -> 0.185 | O5: =N5+$N$62+((BC!$F$125)/'c111 DETERMIACION'!$F$32) -> #DIV/0! | P5: =O5*F5 -> #DIV/0! | Q5: =((O5*0.15)+O5) -> #DIV/0! | R5: =Q5*F5 -> #DIV/0!
A6: ClinChem | B6: 4657608190 | C6: Acido Úrico | D6: 400 | E6: 120 | F6: ='c111'!E12 -> 0 | G6: =F6/D6 -> 0 | H6: =30*BC!$B$47/E6 -> 0 | I6: =IF(H6>G6,H6,G6) -> 0 | J6: =IF(G6=0,0,I6) -> 0 | K6: =ROUNDUP(J6,0) -> 0 | L6: 89 | M6: =L6*K6 -> 0 | N6: =L6/D6 -> 0.2225 | O6: =N6+$N$62+((BC!$F$125)/'c111 DETERMIACION'!$F$32) -> #DIV/0! | P6: =O6*F6 -> #DIV/0! | Q6: =((O6*0.15)+O6) -> #DIV/0! | R6: =Q6*F6 -> #DIV/0!
A7: =F3+F4+F5+F6+F7+F8+F9+F10+F11+F12+F13+F14+F15+F16+F17+F18+F19+F20+F21+F22+F24+F25+F26+F28+F31+F30 -> 0 | B7: 4718917190 | C7: Colesterol | D7: 400 | E7: 120 | F7: ='c111'!E13 -> 0 | G7: =F7/D7 -> 0 | H7: =30*BC!$B$47/E7 -> 0 | I7: =IF(H7>G7,H7,G7) -> 0 | J7: =IF(G7=0,0,I7) -> 0 | K7: =ROUNDUP(J7,0) -> 0 | L7: 83 | M7: =L7*K7 -> 0 | N7: =L7/D7 -> 0.2075 | O7: =N7+$N$62+((BC!$F$125)/'c111 DETERMIACION'!$F$32) -> #DIV/0! | P7: =O7*F7 -> #DIV/0! | Q7: =((O7*0.15)+O7) -> #DIV/0! | R7: =Q7*F7 -> #DIV/0!
B8: 4657594190 | C8: Triglicéridos | D8: 200 | E8: 120 | F8: ='c111'!E14 -> 0 | G8: =F8/D8 -> 0 | H8: =30*BC!$B$47/E8 -> 0 | I8: =IF(H8>G8,H8,G8) -> 0 | J8: =IF(G8=0,0,I8) -> 0 | K8: =ROUNDUP(J8,0) -> 0 | L8: 63 | M8: =L8*K8 -> 0 | N8: =L8/D8 -> 0.315 | O8: =N8+$N$62+((BC!$F$125)/'c111 DETERMIACION'!$F$32) -> #DIV/0! | P8: =O8*F8 -> #DIV/0! | Q8: =((O8*0.15)+O8) -> #DIV/0! | R8: =Q8*F8 -> #DIV/0!
A9: cfas Lipids | B9: 4718569190 | C9: ALT - TGP | D9: 400 | E9: 120 | F9: ='c111'!E15 -> 0 | G9: =F9/D9 -> 0 | H9: =30*BC!$B$47/E9 -> 0 | I9: =IF(H9>G9,H9,G9) -> 0 | J9: =IF(G9=0,0,I9) -> 0 | K9: =ROUNDUP(J9,0) -> 0 | L9: 103 | M9: =L9*K9 -> 0 | N9: =L9/D9 -> 0.2575 | O9: =N9+$N$62+((BC!$F$125)/'c111 DETERMIACION'!$F$32) -> #DIV/0! | P9: =O9*F9 -> #DIV/0! | Q9: =((O9*0.15)+O9) -> #DIV/0! | R9: =Q9*F9 -> #DIV/0!
A10: =SUM(F14+F19) -> 0 | B10: 4657543190 | C10: AST - TGO | D10: 400 | E10: 120 | F10: ='c111'!E16 -> 0 | G10: =F10/D10 -> 0 | H10: =30*BC!$B$47/E10 -> 0 | I10: =IF(H10>G10,H10,G10) -> 0 | J10: =IF(G10=0,0,I10) -> 0 | K10: =ROUNDUP(J10,0) -> 0 | L10: 100 | M10: =L10*K10 -> 0 | N10: =L10/D10 -> 0.25 | O10: =N10+$N$62+((BC!$F$125)/'c111 DETERMIACION'!$F$32) -> #DIV/0! | P10: =O10*F10 -> #DIV/0! | Q10: =((O10*0.15)+O10) -> #DIV/0! | R10: =Q10*F10 -> #DIV/0!
B11: 4657373190 | C11: Fosfatasa alcalina | D11: 200 | E11: 120 | F11: ='c111'!E17 -> 0 | G11: =F11/D11 -> 0 | H11: =30*BC!$B$47/E11 -> 0 | I11: =IF(H11>G11,H11,G11) -> 0 | J11: =IF(G11=0,0,I11) -> 0 | K11: =ROUNDUP(J11,0) -> 0 | L11: 107 | M11: =L11*K11 -> 0 | N11: =L11/D11 -> 0.535 | O11: =N11+$N$62+((BC!$F$125)/'c111 DETERMIACION'!$F$32) -> #DIV/0! | P11: =O11*F11 -> #DIV/0! | Q11: =((O11*0.15)+O11) -> #DIV/0! | R11: =Q11*F11 -> #DIV/0!
B12: 5795648190 | C12: Bilirrubina Total | D12: 400 | E12: 120 | F12: ='c111'!E18 -> 0 | G12: =F12/D12 -> 0 | H12: =30*BC!$B$47/E12 -> 0 | I12: =IF(H12>G12,H12,G12) -> 0 | J12: =IF(G12=0,0,I12) -> 0 | K12: =ROUNDUP(J12,0) -> 0 | L12: 78 | M12: =L12*K12 -> 0 | N12: =L12/D12 -> 0.195 | O12: =N12+$N$62+((BC!$F$125)/'c111 DETERMIACION'!$F$32) -> #DIV/0! | P12: =O12*F12 -> #DIV/0! | Q12: =((O12*0.15)+O12) -> #DIV/0! | R12: =Q12*F12 -> #DIV/0!
B13: 5589134190 | C13: Bilirrubina Directa | D13: 100 | E13: 60 | F13: ='c111'!E19 -> 0 | G13: =F13/D13 -> 0 | H13: =30*BC!$B$47/E13 -> 0 | I13: =IF(H13>G13,H13,G13) -> 0 | J13: =IF(G13=0,0,I13) -> 0 | K13: =ROUNDUP(J13,0) -> 0 | L13: 58 | M13: =L13*K13 -> 0 | N13: =L13/D13 -> 0.58 | O13: =N13+$N$62+((BC!$F$125)/'c111 DETERMIACION'!$F$32) -> #DIV/0! | P13: =O13*F13 -> #DIV/0! | Q13: =((O13*0.15)+O13) -> #DIV/0! | R13: =Q13*F13 -> #DIV/0!
B14: 7528604190 | C14: HDL Colesterol | D14: 200 | E14: 60 | F14: ='c111'!E20 -> 0 | G14: =F14/D14 -> 0 | H14: =30*BC!$B$47/E14 -> 0 | I14: =IF(H14>G14,H14,G14) -> 0 | J14: =IF(G14=0,0,I14) -> 0 | K14: =ROUNDUP(J14,0) -> 0 | L14: 222 | M14: =L14*K14 -> 0 | N14: =L14/D14 -> 1.11 | O14: =N14+$N$62+((BC!$F$125)/'c111 DETERMIACION'!$F$32) -> #DIV/0! | P14: =O14*F14 -> #DIV/0! | Q14: =((O14*0.15)+O14) -> #DIV/0! | R14: =Q14*F14 -> #DIV/0!
B15: 5401496190 | C15: AMILASA | D15: 200 | E15: 60 | F15: ='c111'!E21 -> 0 | G15: =F15/D15 -> 0 | H15: =30*BC!$B$47/E15 -> 0 | I15: =IF(H15>G15,H15,G15) -> 0 | J15: =IF(G15=0,0,I15) -> 0 | K15: =ROUNDUP(J15,0) -> 0 | L15: 138 | M15: =L15*K15 -> 0 | N15: =L15/D15 -> 0.69 | O15: =N15+$N$62+((BC!$F$125)/'c111 DETERMIACION'!$F$32) -> #DIV/0! | P15: =O15*F15 -> #DIV/0! | Q15: =((O15*0.15)+O15) -> #DIV/0! | R15: =Q15*F15 -> #DIV/0!
B16: 5401704190 | C16: LIPASA | D16: 100 | E16: 60 | F16: ='c111'!E22 -> 0 | G16: =F16/D16 -> 0 | H16: =30*BC!$B$47/E16 -> 0 | I16: =IF(H16>G16,H16,G16) -> 0 | J16: =IF(G16=0,0,I16) -> 0 | K16: =ROUNDUP(J16,0) -> 0 | L16: 132 | M16: =L16*K16 -> 0 | N16: =L16/D16 -> 1.32 | O16: =N16+$N$62+((BC!$F$125)/'c111 DETERMIACION'!$F$32) -> #DIV/0! | P16: =O16*F16 -> #DIV/0! | Q16: =((O16*0.15)+O16) -> #DIV/0! | R16: =Q16*F16 -> #DIV/0!
B17: 5401461190 | C17: GGT | D17: 200 | E17: 60 | F17: ='c111'!E23 -> 0 | G17: =F17/D17 -> 0 | H17: =30*BC!$B$47/E17 -> 0 | I17: =IF(H17>G17,H17,G17) -> 0 | J17: =IF(G17=0,0,I17) -> 0 | K17: =ROUNDUP(J17,0) -> 0 | L17: 67 | M17: =L17*K17 -> 0 | N17: =L17/D17 -> 0.335 | O17: =N17+$N$62+((BC!$F$125)/'c111 DETERMIACION'!$F$32) -> #DIV/0! | P17: =O17*F17 -> #DIV/0! | Q17: =((O17*0.15)+O17) -> #DIV/0! | R17: =Q17*F17 -> #DIV/0!
B18: 4657357190 | C18: Albumina | D18: 400 | E18: 120 | F18: ='c111'!E24 -> 0 | G18: =F18/D18 -> 0 | H18: =30*BC!$B$47/E18 -> 0 | I18: =IF(H18>G18,H18,G18) -> 0 | J18: =IF(G18=0,0,I18) -> 0 | K18: =ROUNDUP(J18,0) -> 0 | L18: 85 | M18: =L18*K18 -> 0 | N18: =L18/D18 -> 0.2125 | O18: =N18+$N$62+((BC!$F$125)/'c111 DETERMIACION'!$F$32) -> #DIV/0! | P18: =O18*F18 -> #DIV/0! | Q18: =((O18*0.15)+O18) -> #DIV/0! | R18: =Q18*F18 -> #DIV/0!
B19: 7005806190 | C19: LDL Colesterol | D19: 100 | E19: 60 | F19: ='c111'!E25 -> 0 | G19: =F19/D19 -> 0 | H19: =30*BC!$B$47/E19 -> 0 | I19: =IF(H19>G19,H19,G19) -> 0 | J19: =IF(G19=0,0,I19) -> 0 | K19: =ROUNDUP(J19,0) -> 0 | L19: 109 | M19: =L19*K19 -> 0 | N19: =L19/D19 -> 1.09 | O19: =N19+$N$62+((BC!$F$125)/'c111 DETERMIACION'!$F$32) -> #DIV/0! | P19: =O19*F19 -> #DIV/0! | Q19: =((O19*0.15)+O19) -> #DIV/0! | R19: =Q19*F19 -> #DIV/0!
B20: 5061504190 | C20: Calcio | D20: 400 | E20: 120 | F20: ='c111'!E26 -> 0 | G20: =F20/D20 -> 0 | H20: =30*BC!$B$47/E20 -> 0 | I20: =IF(H20>G20,H20,G20) -> 0 | J20: =IF(G20=0,0,I20) -> 0 | K20: =ROUNDUP(J20,0) -> 0 | L20: 169 | M20: =L20*K20 -> 0 | N20: =L20/D20 -> 0.4225 | O20: =N20+$N$62+((BC!$F$125)/'c111 DETERMIACION'!$F$32) -> #DIV/0! | P20: =O20*F20 -> #DIV/0! | Q20: =((O20*0.15)+O20) -> #DIV/0! | R20: =Q20*F20 -> #DIV/0!
B21: 7442017190 | C21: CK | D21: 200 | E21: 60 | F21: ='c111'!E27 -> 0 | G21: =F21/D21 -> 0 | H21: =30*BC!$B$47/E21 -> 0 | I21: =IF(H21>G21,H21,G21) -> 0 | J21: =IF(G21=0,0,I21) -> 0 | K21: =ROUNDUP(J21,0) -> 0 | L21: 140 | M21: =L21*K21 -> 0 | N21: =L21/D21 -> 0.7 | O21: =N21+$N$62+((BC!$F$125)/'c111 DETERMIACION'!$F$32) -> #DIV/0! | P21: =O21*F21 -> #DIV/0! | Q21: =((O21*0.15)+O21) -> #DIV/0! | R21: =Q21*F21 -> #DIV/0!
B22: 5401674190 | C22: LDH | D22: 100 | E22: 60 | F22: ='c111'!E28 -> 0 | G22: =F22/D22 -> 0 | H22: =30*BC!$B$47/E22 -> 0 | I22: =IF(H22>G22,H22,G22) -> 0 | J22: =IF(G22=0,0,I22) -> 0 | K22: =ROUNDUP(J22,0) -> 0 | L22: 128 | M22: =L22*K22 -> 0 | N22: =L22/D22 -> 1.28 | O22: =N22+$N$62+((BC!$F$125)/'c111 DETERMIACION'!$F$32) -> #DIV/0! | P22: =O22*F22 -> #DIV/0! | Q22: =((O22*0.15)+O22) -> #DIV/0! | R22: =Q22*F22 -> #DIV/0!
... B31: 7442050190 | C31: CK-MB | D31: 100 | E31: 60 | F31: ='c111'!E37 -> 0 | G31: =F31/D31 -> 0 | H31: =30*BC!$B$47/E31 -> 0 | I31: =IF(H31>G31,H31,G31) -> 0 | J31: =IF(G31=0,0,I31) -> 0 | K31: =ROUNDUP(J31,0) -> 0 | L31: 164 | M31: =L31*K31 -> 0 | N31: =L31/D31 -> 1.64 | O31: =N31+$N$62+((BC!$F$125)/'c111 DETERMIACION'!$F$32) -> #DIV/0! | P31: =O31*F31 -> #DIV/0! | Q31: =((O31*0.15)+O31) -> #DIV/0! | R31: =Q31*F31 -> #DIV/0!
D32: TOTAL DET | F32: =SUM(F3:F31) -> 0
B33: CALIBRADOR | K33: MAXIMOS | L33: PVP POR UNIDADES | M33: VALOR POR CAJA | N33: VALOR TOTAL | O33: EN KITS | P33: EN KITS CERRADO
B34: 10759350190 | C34: Calibrator f.a.s. 12x3 ml | D34: 12 | E34: 28 | G34: =(A4/(0.005*400)/3000) -> 0 | H34: =30*BC!$B$47/E34 -> 0 | I34: =IF(G34>H34,G34,H34) -> 0 | J34: =ROUNDUP(I34,0) -> 0 | K34: =IF(A4>0,J34,0) -> 0 | L34: =M34/D34 -> 12 | M34: 144 | N34: =L34*K34 -> 0 | O34: =K34/D34 -> 0 | P34: =ROUNDUP(O34,0) -> 0
B35: 12172623122 | C35: Cfas Lipids 3x1ML | D35: 3 | E35: 28 | G35: =(A10*(0.008*(350/1000))) -> 0 | H35: =30*BC!$B$47/E35 -> 0 | I35: =IF(G35>H35,G35,H35) -> 0 | J35: =ROUNDUP(I35,0) -> 0 | K35: =IF(A10>0,J35,0) -> 0 | L35: =M35/D35 -> 31 | M35: 93 | N35: =L35*K35 -> 0 | O35: =K35/D35 -> 0 | P35: =ROUNDUP(O35,0) -> 0
B36: 11355279216 | C36: Cfas Proteins | D36: 5 | E36: 28 | G36: =(F26*(0.014*(500/2000))) -> 0 | H36: =30*BC!$B$47/E36 -> 0 | I36: =IF(G36>H36,G36,H36) -> 0 | J36: =ROUNDUP(I36,0) -> 0 | K36: =IF(F26>0,J36,0) -> 0 | L36: =M36/D36 -> 29.8 | M36: 149 | N36: =L36*K36 -> 0 | O36: =K36/D36 -> 0 | P36: =ROUNDUP(O36,0) -> 0
B37: 4528417190 | C37: Cfas HbA1c, 3x2ml | D37: 3 | E37: 84 | G37: =(F23*(0.014*(500/2000))) -> 0 | H37: =30*BC!$B$47/E37 -> 0 | I37: =IF(G37>H37,G37,H37) -> 0 | J37: =ROUNDUP(I37,0) -> 0 | K37: =IF(F23>0,J37,0) -> 0 | L37: =M37/D37 -> 150.33333 | M37: 451 | N37: =L37*K37 -> 0 | O37: =K37/D37 -> 0 | P37: =ROUNDUP(O37,0) -> 0
B38: 20751995190 | C38: Ammonia/Ethanol/CO2 Calibrator | D38: 2 | E38: 56 | G38: =(F29*(0.014*(500/2000))) -> 0 | H38: =30*BC!$B$47/E38 -> 0 | I38: =IF(G38>H38,G38,H38) -> 0 | J38: =ROUNDUP(I38,0) -> 0 | K38: =IF(F24>0,J38,0) -> 0 | L38: =M38/D38 -> 313.5 | M38: 627 | N38: =L38*K38 -> 0 | O38: =K38/D38 -> 0 | P38: =ROUNDUP(O38,0) -> 0
B39: 5050901190 | C39: Cfas D- Dimer | D39: 1 | E39: 84 | G39: =(F27*(0.014*(500/2000))) -> 0 | H39: =30*BC!$B$47/E39 -> 0 | I39: =IF(G39>H39,G39,H39) -> 0 | J39: =ROUNDUP(I39,0) -> 0 | K39: =IF(F27>0,J39,0) -> 0 | L39: =M39/D39 -> 282 | M39: 282 | N39: =L39*K39 -> 0 | O39: =K39/D39 -> 0 | P39: =ROUNDUP(O39,0) -> 0
B40: 11447394216 | C40: Calibrator f.a.s. CK‑MB | D40: 3 | E40: 28 | G40: =(F31*(0.014*(500/2000))) -> 0 | H40: =30*BC!$B$47/E40 -> 0 | I40: =IF(G40>H40,G40,H40) -> 0 | J40: =ROUNDUP(I40,0) -> 0 | K40: =IF(F28>0,J40,0) -> 0 | L40: =M40/D40 -> 25.333333 | M40: 76 | N40: =L40*K40 -> 0 | O40: =K40/D40 -> 0 | P40: =ROUNDUP(O40,0) -> 0
B41: CONTROL
B42: 5947626190 | C42: PreciControl ClinChem Multi 1 4x5ml | D42: 4 | E42: 14 | G42: =(A7/(0.003*350)/5000) -> 0 | H42: =30*BC!$B$47/E42 -> 0 | I42: =IF(G42>H42,G42,H42) -> 0 | J42: =ROUNDUP(I42,0) -> 0 | K42: =IF(F32>0,J42,0) -> 0 | L42: =M42/D42 -> 14.25 | M42: 57 | N42: =L42*K42 -> 0 | O42: =K42/D42 -> 0 | P42: =ROUNDUP(O42,0) -> 0
B43: 5947774190 | C43: PreciControl ClinChem Multi 2 4x5ml | D43: 4 | E43: 14 | G43: =(A7/(0.003*350)/5000) -> 0 | H43: =30*BC!$B$47/E43 -> 0 | I43: =IF(G43>H43,G43,H43) -> 0 | J43: =ROUNDUP(I43,0) -> 0 | K43: =IF(F32>0,J43,0) -> 0 | L43: =M43/D43 -> 22.75 | M43: 91 | N43: =L43*K43 -> 0 | O43: =K43/D43 -> 0 | P43: =ROUNDUP(O43,0) -> 0
B44: 5479207190 | C44: PreciControl HBA1c Norm | D44: 4 | E44: 28 | G44: =(F23/(0.0007*150)/1000) -> 0 | H44: =30*BC!$B$47/E44 -> 0 | I44: =IF(G44>H44,G44,H44) -> 0 | J44: =ROUNDUP(I44,0) -> 0 | K44: =IF(F23>0,J44,0) -> 0 | L44: =M44/D44 -> 77.25 | M44: 309 | N44: =L44*K44 -> 0 | O44: =K44/D44 -> 0 | P44: =ROUNDUP(O44,0) -> 0
B45: 5912504190 | C45: PRECICONTROL HBA1C PATH | D45: 4 | E45: 28 | G45: =(F23/(0.0007*150)/1000) -> 0 | H45: =30*BC!$B$47/E45 -> 0 | I45: =IF(G45>H45,G45,H45) -> 0 | J45: =ROUNDUP(I45,0) -> 0 | K45: =IF(F23>0,J45,0) -> 0 | L45: =M45/D45 -> 154.5 | M45: 618 | N45: =L45*K45 -> 0 | O45: =K45/D45 -> 0 | P45: =ROUNDUP(O45,0) -> 0
B46: 20752401190 | C46: Ammonia/Ethanol/CO2 Control Normal | D46: 5 | E46: 56 | G46: =(F29/(0.0007*150)/1000) -> 0 | H46: =30*BC!$B$47/E46 -> 0 | I46: =IF(G46>H46,G46,H46) -> 0 | J46: =ROUNDUP(I46,0) -> 0 | K46: =IF(F24>0,J46,0) -> 0 | L46: =M46/D46 -> 41.4 | M46: 207 | N46: =L46*K46 -> 0 | O46: =K46/D46 -> 0 | P46: =ROUNDUP(O46,0) -> 0
B47: 20753009190 | C47: Ammonia/Ethanol/CO2 Control Normal | D47: 5 | E47: 56 | G47: =F29/(0.0007*150)/1000 -> 0 | H47: =30*BC!$B$47/E47 -> 0 | I47: =IF(G47>H47,G47,H47) -> 0 | J47: =ROUNDUP(I47,0) -> 0 | K47: =IF(F25>0,J47,0) -> 0 | L47: =M47/D47 -> 45.4 | M47: 227 | N47: =L47*K47 -> 0 | O47: =K47/D47 -> 0 | P47: =ROUNDUP(O47,0) -> 0
B48: 5050936190 | C48: PreciControl D- Dimer | D48: 2 | E48: 84 | G48: =(F27/(0.0004*300)/3000) -> 0 | H48: =30*BC!$B$47/E48 -> 0 | I48: =IF(G48>H48,G48,H48) -> 0 | J48: =ROUNDUP(I48,0) -> 0 | K48: =IF(F27>0,J48,0) -> 0 | L48: =M48/D48 -> 244 | M48: 488 | N48: =L48*K48 -> 0 | O48: =K48/D48 -> 0 | P48: =ROUNDUP(O48,0) -> 0
B49: CONSUMIBLES
...

Sheet c111 PRUEBA EFECTIVA
B2: ID | C2: REACTIVO | D2: DET/KIT | E2: DIAS ESTABILIDAD | F2: CANTIDAD PROCESO/AÑO | G2: PARA PRUEBA EFECTIVA | H2: PRODUCTO CALCULADO | I2: MINIMOS POR ESTABILIDAD | J2: PRODUCTO A ENTREGAR | L2: REDONDEADO A ENTREGAR | M2: PVP | N2: TOTAL | O2: $ DETERMINACION | P2: $DETERMINACION CON CONSUMIBLES Y EXTRAS | Q2: TOTAL CON CONSUMIBLES Y EXTRAS | R2: $ PARA PROCESO | S2: TOTAL PARA PROCESO | T2: VALOR INICIAL DEL PROCESO | U2: VALOR FINAL DEL PROCESO
A3: =SUM(G3+G4+G5+G6+G7+G8+G9+G10+G11+G12+G13+G15+G16+G17+G18+G20+G21+G22+G24+G25+G28) -> 0 | B3: 4657527190 | C3: Glucosa | D3: 400 | E3: 120 | F3: ='c111'!E9 -> 0 | G3: =((F3*0.2)+(F3)) -> 0 | H3: =G3/D3 -> 0 | I3: =30*BC!$B$47/E3 -> 0 | J3: =IF(I3>H3,I3,H3) -> 0 | K3: =IF(H3=0,0,J3) -> 0 | L3: =ROUNDUP(K3,0) -> 0 | M3: 50 | N3: =M3*L3 -> 0 | O3: =M3/D3 -> 0.125 | P3: =O3+$O$62+((BC!$F$125)/'c111 DETERMIACION'!$F$32) -> #DIV/0! | Q3: =P3*F3 -> #DIV/0! | R3: =((P3*0.15)+P3) -> #DIV/0! | S3: =R3*F3 -> #DIV/0! | T3: =SUM(S3:S31) -> #DIV/0! | U3: =SUM(Q3:Q31) -> #DIV/0!
A4: =G3+G4+G5+G6+G7+G8+G9+G10+G11+G12+G13+G14+G15+G16+G17+G18+G19+G20+G21+G22+G24+G25+G26+G28 -> 0 | B4: 4657616190 | C4: Urea | D4: 400 | E4: 120 | F4: ='c111'!E10 -> 0 | G4: =((F4*0.2)+(F4)) -> 0 | H4: =G4/D4 -> 0 | I4: =30*BC!$B$47/E4 -> 0 | J4: =IF(I4>H4,I4,H4) -> 0 | K4: =IF(H4=0,0,J4) -> 0 | L4: =ROUNDUP(K4,0) -> 0 | M4: 62 | N4: =M4*L4 -> 0 | O4: =M4/D4 -> 0.155 | P4: =O4+$O$62+((BC!$F$125)/'c111 DETERMIACION'!$F$32) -> #DIV/0! | Q4: =P4*F4 -> #DIV/0! | R4: =((P4*0.15)+P4) -> #DIV/0! | S4: =R4*F4 -> #DIV/0!
B5: 5401755190 | C5: Creatinina | D5: 400 | E5: 120 | F5: ='c111'!E11 -> 0 | G5: =((F5*0.2)+(F5)) -> 0 | H5: =G5/D5 -> 0 | I5: =30*BC!$B$47/E5 -> 0 | J5: =IF(I5>H5,I5,H5) -> 0 | K5: =IF(H5=0,0,J5) -> 0 | L5: =ROUNDUP(K5,0) -> 0 | M5: 74 | N5: =M5*L5 -> 0 | O5: =M5/D5 -> 0.185 | P5: =O5+$O$62+((BC!$F$125)/'c111 DETERMIACION'!$F$32) -> #DIV/0! | Q5: =P5*F5 -> #DIV/0! | R5: =((P5*0.15)+P5) -> #DIV/0! | S5: =R5*F5 -> #DIV/0!
B6: 4657608190 | C6: Acido Úrico | D6: 400 | E6: 120 | F6: ='c111'!E12 -> 0 | G6: =((F6*0.2)+(F6)) -> 0 | H6: =G6/D6 -> 0 | I6: =30*BC!$B$47/E6 -> 0 | J6: =IF(I6>H6,I6,H6) -> 0 | K6: =IF(H6=0,0,J6) -> 0 | L6: =ROUNDUP(K6,0) -> 0 | M6: 89 | N6: =M6*L6 -> 0 | O6: =M6/D6 -> 0.2225 | P6: =O6+$O$62+((BC!$F$125)/'c111 DETERMIACION'!$F$32) -> #DIV/0! | Q6: =P6*F6 -> #DIV/0! | R6: =((P6*0.15)+P6) -> #DIV/0! | S6: =R6*F6 -> #DIV/0!
B7: 4718917190 | C7: Colesterol | D7: 400 | E7: 120 | F7: ='c111'!E13 -> 0 | G7: =((F7*0.2)+(F7)) -> 0 | H7: =G7/D7 -> 0 | I7: =30*BC!$B$47/E7 -> 0 | J7: =IF(I7>H7,I7,H7) -> 0 | K7: =IF(H7=0,0,J7) -> 0 | L7: =ROUNDUP(K7,0) -> 0 | M7: 83 | N7: =M7*L7 -> 0 | O7: =M7/D7 -> 0.2075 | P7: =O7+$O$62+((BC!$F$125)/'c111 DETERMIACION'!$F$32) -> #DIV/0! | Q7: =P7*F7 -> #DIV/0! | R7: =((P7*0.15)+P7) -> #DIV/0! | S7: =R7*F7 -> #DIV/0!
B8: 4657594190 | C8: Triglicéridos | D8: 200 | E8: 120 | F8: ='c111'!E14 -> 0 | G8: =((F8*0.2)+(F8)) -> 0 | H8: =G8/D8 -> 0 | I8: =30*BC!$B$47/E8 -> 0 | J8: =IF(I8>H8,I8,H8) -> 0 | K8: =IF(H8=0,0,J8) -> 0 | L8: =ROUNDUP(K8,0) -> 0 | M8: 63 | N8: =M8*L8 -> 0 | O8: =M8/D8 -> 0.315 | P8: =O8+$O$62+((BC!$F$125)/'c111 DETERMIACION'!$F$32) -> #DIV/0! | Q8: =P8*F8 -> #DIV/0! | R8: =((P8*0.15)+P8) -> #DIV/0! | S8: =R8*F8 -> #DIV/0!
B9: 4718569190 | C9: ALT - TGP | D9: 400 | E9: 120 | F9: ='c111'!E15 -> 0 | G9: =((F9*0.2)+(F9)) -> 0 | H9: =G9/D9 -> 0 | I9: =30*BC!$B$47/E9 -> 0 | J9: =IF(I9>H9,I9,H9) -> 0 | K9: =IF(H9=0,0,J9) -> 0 | L9: =ROUNDUP(K9,0) -> 0 | M9: 103 | N9: =M9*L9 -> 0 | O9: =M9/D9 -> 0.2575 | P9: =O9+$O$62+((BC!$F$125)/'c111 DETERMIACION'!$F$32) -> #DIV/0! | Q9: =P9*F9 -> #DIV/0! | R9: =((P9*0.15)+P9) -> #DIV/0! | S9: =R9*F9 -> #DIV/0!
B10: 4657543190 | C10: AST - TGO | D10: 400 | E10: 120 | F10: ='c111'!E16 -> 0 | G10: =((F10*0.2)+(F10)) -> 0 | H10: =G10/D10 -> 0 | I10: =30*BC!$B$47/E10 -> 0 | J10: =IF(I10>H10,I10,H10) -> 0 | K10: =IF(H10=0,0,J10) -> 0 | L10: =ROUNDUP(K10,0) -> 0 | M10: 100 | N10: =M10*L10 -> 0 | O10: =M10/D10 -> 0.25 | P10: =O10+$O$62+((BC!$F$125)/'c111 DETERMIACION'!$F$32) -> #DIV/0! | Q10: =P10*F10 -> #DIV/0! | R10: =((P10*0.15)+P10) -> #DIV/0! | S10: =R10*F10 -> #DIV/0!
B11: 4657373190 | C11: Fosfatasa alcalina | D11: 200 | E11: 120 | F11: ='c111'!E17 -> 0 | G11: =((F11*0.2)+(F11)) -> 0 | H11: =G11/D11 -> 0 | I11: =30*BC!$B$47/E11 -> 0 | J11: =IF(I11>H11,I11,H11) -> 0 | K11: =IF(H11=0,0,J11) -> 0 | L11: =ROUNDUP(K11,0) -> 0 | M11: 107 | N11: =M11*L11 -> 0 | O11: =M11/D11 -> 0.535 | P11: =O11+$O$62+((BC!$F$125)/'c111 DETERMIACION'!$F$32) -> #DIV/0! | Q11: =P11*F11 -> #DIV/0! | R11: =((P11*0.15)+P11) -> #DIV/0! | S11: =R11*F11 -> #DIV/0!
B12: 5795648190 | C12: Bilirrubina Total | D12: 400 | E12: 120 | F12: ='c111'!E18 -> 0 | G12: =((F12*0.2)+(F12)) -> 0 | H12: =G12/D12 -> 0 | I12: =30*BC!$B$47/E12 -> 0 | J12: =IF(I12>H12,I12,H12) -> 0 | K12: =IF(H12=0,0,J12) -> 0 | L12: =ROUNDUP(K12,0) -> 0 | M12: 78 | N12: =M12*L12 -> 0 | O12: =M12/D12 -> 0.195 | P12: =O12+$O$62+((BC!$F$125)/'c111 DETERMIACION'!$F$32) -> #DIV/0! | Q12: =P12*F12 -> #DIV/0! | R12: =((P12*0.15)+P12) -> #DIV/0! | S12: =R12*F12 -> #DIV/0!
B13: 5589134190 | C13: Bilirrubina Directa | D13: 100 | E13: 60 | F13: ='c111'!E19 -> 0 | G13: =((F13*0.2)+(F13)) -> 0 | H13: =G13/D13 -> 0 | I13: =30*BC!$B$47/E13 -> 0 | J13: =IF(I13>H13,I13,H13) -> 0 | K13: =IF(H13=0,0,J13) -> 0 | L13: =ROUNDUP(K13,0) -> 0 | M13: 58 | N13: =M13*L13 -> 0 | O13: =M13/D13 -> 0.58 | P13: =O13+$O$62+((BC!$F$125)/'c111 DETERMIACION'!$F$32) -> #DIV/0! | Q13: =P13*F13 -> #DIV/0! | R13: =((P13*0.15)+P13) -> #DIV/0! | S13: =R13*F13 -> #DIV/0!
A14: =SUM(G14+G19) -> 0 | B14: 7528604190 | C14: HDL Colesterol | D14: 200 | E14: 60 | F14: ='c111'!E20 -> 0 | G14: =((F14*0.2)+(F14)) -> 0 | H14: =G14/D14 -> 0 | I14: =30*BC!$B$47/E14 -> 0 | J14: =IF(I14>H14,I14,H14) -> 0 | K14: =IF(H14=0,0,J14) -> 0 | L14: =ROUNDUP(K14,0) -> 0 | M14: 222 | N14: =M14*L14 -> 0 | O14: =M14/D14 -> 1.11 | P14: =O14+$O$62+((BC!$F$125)/'c111 DETERMIACION'!$F$32) -> #DIV/0! | Q14: =P14*F14 -> #DIV/0! | R14: =((P14*0.15)+P14) -> #DIV/0! | S14: =R14*F14 -> #DIV/0!
B15: 5401496190 | C15: AMILASA | D15: 200 | E15: 60 | F15: ='c111'!E21 -> 0 | G15: =((F15*0.2)+(F15)) -> 0 | H15: =G15/D15 -> 0 | I15: =30*BC!$B$47/E15 -> 0 | J15: =IF(I15>H15,I15,H15) -> 0 | K15: =IF(H15=0,0,J15) -> 0 | L15: =ROUNDUP(K15,0) -> 0 | M15: 138 | N15: =M15*L15 -> 0 | O15: =M15/D15 -> 0.69 | P15: =O15+$O$62+((BC!$F$125)/'c111 DETERMIACION'!$F$32) -> #DIV/0! | Q15: =P15*F15 -> #DIV/0! | R15: =((P15*0.15)+P15) -> #DIV/0! | S15: =R15*F15 -> #DIV/0!
B16: 5401704190 | C16: LIPASA | D16: 100 | E16: 60 | F16: ='c111'!E22 -> 0 | G16: =((F16*0.2)+(F16)) -> 0 | H16: =G16/D16 -> 0 | I16: =30*BC!$B$47/E16 -> 0 | J16: =IF(I16>H16,I16,H16) -> 0 | K16: =IF(H16=0,0,J16) -> 0 | L16: =ROUNDUP(K16,0) -> 0 | M16: 132 | N16: =M16*L16 -> 0 | O16: =M16/D16 -> 1.32 | P16: =O16+$O$62+((BC!$F$125)/'c111 DETERMIACION'!$F$32) -> #DIV/0! | Q16: =P16*F16 -> #DIV/0! | R16: =((P16*0.15)+P16) -> #DIV/0! | S16: =R16*F16 -> #DIV/0!
B17: 5401461190 | C17: GGT | D17: 200 | E17: 60 | F17: ='c111'!E23 -> 0 | G17: =((F17*0.2)+(F17)) -> 0 | H17: =G17/D17 -> 0 | I17: =30*BC!$B$47/E17 -> 0 | J17: =IF(I17>H17,I17,H17) -> 0 | K17: =IF(H17=0,0,J17) -> 0 | L17: =ROUNDUP(K17,0) -> 0 | M17: 67 | N17: =M17*L17 -> 0 | O17: =M17/D17 -> 0.335 | P17: =O17+$O$62+((BC!$F$125)/'c111 DETERMIACION'!$F$32) -> #DIV/0! | Q17: =P17*F17 -> #DIV/0! | R17: =((P17*0.15)+P17) -> #DIV/0! | S17: =R17*F17 -> #DIV/0!
B18: 4657357190 | C18: Albumina | D18: 400 | E18: 120 | F18: ='c111'!E24 -> 0 | G18: =((F18*0.2)+(F18)) -> 0 | H18: =G18/D18 -> 0 | I18: =30*BC!$B$47/E18 -> 0 | J18: =IF(I18>H18,I18,H18) -> 0 | K18: =IF(H18=0,0,J18) -> 0 | L18: =ROUNDUP(K18,0) -> 0 | M18: 85 | N18: =M18*L18 -> 0 | O18: =M18/D18 -> 0.2125 | P18: =O18+$O$62+((BC!$F$125)/'c111 DETERMIACION'!$F$32) -> #DIV/0! | Q18: =P18*F18 -> #DIV/0! | R18: =((P18*0.15)+P18) -> #DIV/0! | S18: =R18*F18 -> #DIV/0!
B19: 7005806190 | C19: LDL Colesterol | D19: 100 | E19: 60 | F19: ='c111'!E25 -> 0 | G19: =((F19*0.2)+(F19)) -> 0 | H19: =G19/D19 -> 0 | I19: =30*BC!$B$47/E19 -> 0 | J19: =IF(I19>H19,I19,H19) -> 0 | K19: =IF(H19=0,0,J19) -> 0 | L19: =ROUNDUP(K19,0) -> 0 | M19: 109 | N19: =M19*L19 -> 0 | O19: =M19/D19 -> 1.09 | P19: =O19+$O$62+((BC!$F$125)/'c111 DETERMIACION'!$F$32) -> #DIV/0! | Q19: =P19*F19 -> #DIV/0! | R19: =((P19*0.15)+P19) -> #DIV/0! | S19: =R19*F19 -> #DIV/0!
B20: 5061504190 | C20: Calcio | D20: 400 | E20: 120 | F20: ='c111'!E26 -> 0 | G20: =((F20*0.2)+(F20)) -> 0 | H20: =G20/D20 -> 0 | I20: =30*BC!$B$47/E20 -> 0 | J20: =IF(I20>H20,I20,H20) -> 0 | K20: =IF(H20=0,0,J20) -> 0 | L20: =ROUNDUP(K20,0) -> 0 | M20: 169 | N20: =M20*L20 -> 0 | O20: =M20/D20 -> 0.4225 | P20: =O20+$O$62+((BC!$F$125)/'c111 DETERMIACION'!$F$32) -> #DIV/0! | Q20: =P20*F20 -> #DIV/0! | R20: =((P20*0.15)+P20) -> #DIV/0! | S20: =R20*F20 -> #DIV/0!
B21: 7442017190 | C21: CK | D21: 200 | E21: 60 | F21: ='c111'!E27 -> 0 | G21: =((F21*0.2)+(F21)) -> 0 | H21: =G21/D21 -> 0 | I21: =30*BC!$B$47/E21 -> 0 | J21: =IF(I21>H21,I21,H21) -> 0 | K21: =IF(H21=0,0,J21) -> 0 | L21: =ROUNDUP(K21,0) -> 0 | M21: 140 | N21: =M21*L21 -> 0 | O21: =M21/D21 -> 0.7 | P21: =O21+$O$62+((BC!$F$125)/'c111 DETERMIACION'!$F$32) -> #DIV/0! | Q21: =P21*F21 -> #DIV/0! | R21: =((P21*0.15)+P21) -> #DIV/0! | S21: =R21*F21 -> #DIV/0!
B22: 5401674190 | C22: LDH | D22: 100 | E22: 60 | F22: ='c111'!E28 -> 0 | G22: =((F22*0.2)+(F22)) -> 0 | H22: =G22/D22 -> 0 | I22: =30*BC!$B$47/E22 -> 0 | J22: =IF(I22>H22,I22,H22) -> 0 | K22: =IF(H22=0,0,J22) -> 0 | L22: =ROUNDUP(K22,0) -> 0 | M22: 128 | N22: =M22*L22 -> 0 | O22: =M22/D22 -> 1.28 | P22: =O22+$O$62+((BC!$F$125)/'c111 DETERMIACION'!$F$32) -> #DIV/0! | Q22: =P22*F22 -> #DIV/0! | R22: =((P22*0.15)+P22) -> #DIV/0! | S22: =R22*F22 -> #DIV/0!
B23: 5336180190 | C23: HbA1c | D23: 200 | E23: 60 | F23: ='c111'!E29 -> 0 | G23: =((F23*0.2)+(F23)) -> 0 | H23: =G23/D23 -> 0 | I23: =30*BC!$B$47/E23 -> 0 | J23: =IF(I23>H23,I23,H23) -> 0 | K23: =IF(H23=0,0,J23) -> 0 | L23: =ROUNDUP(K23,0) -> 0 | M23: 310 | N23: =M23*L23 -> 0 | O23: =M23/D23 -> 1.55 | P23: =O23+$O$62+((BC!$F$125)/'c111 DETERMIACION'!$F$32) -> #DIV/0! | Q23: =P23*F23 -> #DIV/0! | R23: =((P23*0.15)+P23) -> #DIV/0! | S23: =R23*F23 -> #DIV/0!
B24: 5401658190 | C24: Hierro | D24: 100 | E24: 60 | F24: ='c111'!E30 -> 0 | G24: =((F24*0.2)+(F24)) -> 0 | H24: =G24/D24 -> 0 | I24: =30*BC!$B$47/E24 -> 0 | J24: =IF(I24>H24,I24,H24) -> 0 | K24: =IF(H24=0,0,J24) -> 0 | L24: =ROUNDUP(K24,0) -> 0 | M24: 87 | N24: =M24*L24 -> 0 | O24: =M24/D24 -> 0.87 | P24: =O24+$O$62+((BC!$F$125)/'c111 DETERMIACION'!$F$32) -> #DIV/0! | Q24: =P24*F24 -> #DIV/0! | R24: =((P24*0.15)+P24) -> #DIV/0! | S24: =R24*F24 -> #DIV/0!
B25: 4657586190 | C25: Proteinas totales | D25: 400 | E25: 120 | F25: ='c111'!E31 -> 0 | G25: =((F25*0.2)+(F25)) -> 0 | H25: =G25/D25 -> 0 | I25: =30*BC!$B$47/E25 -> 0 | J25: =IF(I25>H25,I25,H25) -> 0 | K25: =IF(H25=0,0,J25) -> 0 | L25: =ROUNDUP(K25,0) -> 0 | M25: 80 | N25: =M25*L25 -> 0 | O25: =M25/D25 -> 0.2 | P25: =O25+$O$62+((BC!$F$125)/'c111 DETERMIACION'!$F$32) -> #DIV/0! | Q25: =P25*F25 -> #DIV/0! | R25: =((P25*0.15)+P25) -> #DIV/0! | S25: =R25*F25 -> #DIV/0!
B26: 7876432190 | C26: PCR latex | D26: 200 | E26: 60 | F26: ='c111'!E32 -> 0 | G26: =((F26*0.2)+(F26)) -> 0 | H26: =G26/D26 -> 0 | I26: =30*BC!$B$47/E26 -> 0 | J26: =IF(I26>H26,I26,H26) -> 0 | K26: =IF(H26=0,0,J26) -> 0 | L26: =ROUNDUP(K26,0) -> 0 | M26: 180 | N26: =M26*L26 -> 0 | O26: =M26/D26 -> 0.9 | P26: =O26+$O$62+((BC!$F$125)/'c111 DETERMIACION'!$F$32) -> #DIV/0! | Q26: =P26*F26 -> #DIV/0! | R26: =((P26*0.15)+P26) -> #DIV/0! | S26: =R26*F26 -> #DIV/0!
... B28: 5401780190 | C28: Phosforo | D28: 100 | E28: 60 | F28: ='c111'!E34 -> 0 | G28: =((F28*0.2)+(F28)) -> 0 | H28: =G28/D28 -> 0 | I28: =30*BC!$B$47/E28 -> 0 | J28: =IF(I28>H28,I28,H28) -> 0 | K28: =IF(H28=0,0,J28) -> 0 | L28: =ROUNDUP(K28,0) -> 0 | M28: 136 | N28: =M28*L28 -> 0 | O28: =M28/D28 -> 1.36 | P28: =O28+$O$62+((BC!$F$125)/'c111 DETERMIACION'!$F$32) -> #DIV/0! | Q28: =P28*F28 -> #DIV/0! | R28: =((P28*0.15)+P28) -> #DIV/0! | S28: =R28*F28 -> #DIV/0!
B29: 5401739190 | C29: NH3L Ammonia | D29: 100 | E29: 56 | F29: ='c111'!E35 -> 0 | G29: =((F29*0.2)+(F29)) -> 0 | H29: =F29/D29 -> 0 | I29: =30*BC!$B$47/E29 -> 0 | J29: =IF(I29>H29,I29,H29) -> 0 | K29: =IF(H29=0,0,J29) -> 0 | L29: =ROUNDUP(K29,0) -> 0 | M29: 221 | N29: =M29*L29 -> 0 | O29: =M29/D29 -> 2.21 | P29: =O29+$O$62+((BC!$F$125)/'c111 DETERMIACION'!$F$32) -> #DIV/0! | Q29: =P29*F29 -> #DIV/0! | R29: =((P29*0.15)+P29) -> #DIV/0! | S29: =R29*F29 -> #DIV/0!
B30: 8900019190 | C30: MG2, 100T, COBAS C 111 | D30: 100 | E30: 56 | F30: ='c111'!E36 -> 0 | G30: =((F30*0.2)+(F30)) -> 0 | H30: =F30/D30 -> 0 | I30: =30*BC!$B$47/E30 -> 0 | J30: =IF(I30>H30,I30,H30) -> 0 | K30: =IF(H30=0,0,J30) -> 0 | L30: =ROUNDUP(K30,0) -> 0 | M30: 90 | N30: =M30*L30 -> 0 | O30: =M30/D30 -> 0.9 | P30: =O30+$O$62+((BC!$F$125)/'c111 DETERMIACION'!$F$32) -> #DIV/0! | Q30: =P30*F30 -> #DIV/0! | R30: =((P30*0.15)+P30) -> #DIV/0! | S30: =R30*F30 -> #DIV/0!
B31: 7442050190 | C31: CK-MB | D31: 100 | E31: 60 | F31: ='c111'!E37 -> 0 | G31: =((F31*0.2)+(F31)) -> 0 | H31: =G31/D31 -> 0 | I31: =30*BC!$B$47/E31 -> 0 | J31: =IF(I31>H31,I31,H31) -> 0 | K31: =IF(H31=0,0,J31) -> 0 | L31: =ROUNDUP(K31,0) -> 0 | M31: 164 | N31: =M31*L31 -> 0 | O31: =M31/D31 -> 1.64 | P31: =O31+$O$62+((BC!$F$125)/'c111 DETERMIACION'!$F$32) -> #DIV/0! | Q31: =P31*F31 -> #DIV/0! | R31: =((P31*0.15)+P31) -> #DIV/0! | S31: =R31*F31 -> #DIV/0!
D32: TOTAL DET | F32: =SUM(F3:F31) -> 0 | G32: =SUM(G3:G31) -> 0
B33: CALIBRADOR | D33: PRESENTACION | E33: DIAS ESTABILIDAD | H33: PRODUCTO CALCULADO | I33: MINIMOS POR ESTABILIDAD | J33: PRODUCTO A ENTREGAR | L33: MAXIMOS | M33: PVP POR UNIDADES | N33: VALOR POR CAJA | O33: VALOR TOTAL | P33: EN KITS | Q33: EN KITS CERRADO
B34: 10759350190 | C34: Calibrator f.a.s. 12x3 ml | D34: 12 | E34: 28 | H34: =(A3/(0.005*400)/3000) -> 0 | I34: =30*BC!$B$47/E34 -> 0 | J34: =IF(H34>I34,H34,I34) -> 0 | K34: =ROUNDUP(J34,0) -> 0 | L34: =IF(A3>0,K34,0) -> 0 | M34: =N34/D34 -> 12 | N34: 144 | O34: =M34*L34 -> 0 | P34: =L34/D34 -> 0 | Q34: =ROUNDUP(P34,0) -> 0
B35: 12172623122 | C35: Cfas Lipids 3x1ML | D35: 3 | E35: 28 | H35: =(A14*(0.008*(350/1000))) -> 0 | I35: =30*BC!$B$47/E35 -> 0 | J35: =IF(H35>I35,H35,I35) -> 0 | K35: =ROUNDUP(J35,0) -> 0 | L35: =IF(A14>0,K35,0) -> 0 | M35: =N35/D35 -> 31 | N35: 93 | O35: =M35*L35 -> 0 | P35: =L35/D35 -> 0 | Q35: =ROUNDUP(P35,0) -> 0
B36: 11355279216 | C36: Cfas Proteins | D36: 5 | E36: 28 | H36: =(G26*(0.014*(500/2000))) -> 0 | I36: =30*BC!$B$47/E36 -> 0 | J36: =IF(H36>I36,H36,I36) -> 0 | K36: =ROUNDUP(J36,0) -> 0 | L36: =IF(F26>0,K36,0) -> 0 | M36: =N36/D36 -> 29.8 | N36: 149 | O36: =M36*L36 -> 0 | P36: =L36/D36 -> 0 | Q36: =ROUNDUP(P36,0) -> 0
B37: 4528417190 | C37: Cfas HbA1c, 3x2ml | D37: 3 | E37: 84 | H37: =(G23*(0.014*(500/2000))) -> 0 | I37: =30*BC!$B$47/E37 -> 0 | J37: =IF(H37>I37,H37,I37) -> 0 | K37: =ROUNDUP(J37,0) -> 0 | L37: =IF(F23>0,K37,0) -> 0 | M37: =N37/D37 -> 150.33333 | N37: 451 | O37: =M37*L37 -> 0 | P37: =L37/D37 -> 0 | Q37: =ROUNDUP(P37,0) -> 0
B38: 20751995190 | C38: Ammonia/Ethanol/CO2 Calibrator | D38: 2 | E38: 56 | H38: =(F29*(0.014*(500/2000))) -> 0 | I38: =30*BC!$B$47/E38 -> 0 | J38: =IF(H38>I38,H38,I38) -> 0 | K38: =ROUNDUP(J38,0) -> 0 | L38: =IF(F24>0,K38,0) -> 0 | M38: =N38/D38 -> 313.5 | N38: 627 | O38: =M38*L38 -> 0 | P38: =L38/D38 -> 0 | Q38: =ROUNDUP(P38,0) -> 0
B39: 5050901190 | C39: Cfas D- Dimer | D39: 1 | E39: 84 | H39: =(G27*(0.014*(500/2000))) -> 0 | I39: =30*BC!$B$47/E39 -> 0 | J39: =IF(H39>I39,H39,I39) -> 0 | K39: =ROUNDUP(J39,0) -> 0 | L39: =IF(F27>0,K39,0) -> 0 | M39: =N39/D39 -> 282 | N39: 282 | O39: =M39*L39 -> 0 | P39: =L39/D39 -> 0 | Q39: =ROUNDUP(P39,0) -> 0
B40: 11447394216 | C40: Calibrator f.a.s. CK‑MB | D40: 3 | E40: 28 | H40: =(G31*(0.014*(500/2000))) -> 0 | I40: =30*BC!$B$47/E40 -> 0 | J40: =IF(H40>I40,H40,I40) -> 0 | K40: =ROUNDUP(J40,0) -> 0 | L40: =IF(F28>0,K40,0) -> 0 | M40: =N40/D40 -> 25.333333 | N40: 76 | O40: =M40*L40 -> 0 | P40: =L40/D40 -> 0 | Q40: =ROUNDUP(P40,0) -> 0
B41: CONTROL
B42: 5947626190 | C42: PreciControl ClinChem Multi 1 4x5ml | D42: 4 | E42: 14 | H42: =(A4/(0.003*350)/5000) -> 0 | I42: =30*BC!$B$47/E42 -> 0 | J42: =IF(H42>I42,H42,I42) -> 0 | K42: =ROUNDUP(J42,0) -> 0 | L42: =IF(F32>0,K42,0) -> 0 | M42: =N42/D42 -> 14.25 | N42: 57 | O42: =M42*L42 -> 0 | P42: =L42/D42 -> 0 | Q42: =ROUNDUP(P42,0) -> 0
...

Sheet c111 TODO COMPRADO
B2: ID | C2: REACTIVO | D2: DET/KIT | E2: DIAS ESTABILIDAD | F2: CANTIDAD PROCESO/AÑO | G2: PRODUCTO CALCULADO | H2: MINIMOS POR ESTABILIDAD | I2: PRODUCTO A ENTREGAR | K2: REDONDEADO A ENTREGAR | L2: PVP | M2: TOTAL | N2: PVP TODO COMPRADO | O2: TOTAL PVP TODO COMPRADO | P2: $ DETERMINACION | Q2: $DETERMINACION CON CONSUMIBLES Y EXTRAS | R2: TOTAL CON CONSUMIBLES Y EXTRAS | S2: $ PARA PROCESO | T2: TOTAL PARA PROCESO | U2: VALOR INICIAL DEL PROCESO | V2: VALOR FINAL DEL PROCESO
A3: =SUM(F3+F4+F5+F6+F7+F8+F9+F10+F11+F12+F13+F15+F16+F17+F18+F20+F21+F22+F24+F25+F28) -> 0 | B3: 4657527190 | C3: Glucosa | D3: 400 | E3: 120 | F3: ='c111'!E9 -> 0 | G3: =F3/D3 -> 0 | H3: =30*BC!B47/E3 -> 0 | I3: =IF(H3>G3,H3,G3) -> 0 | J3: =IF(G3=0,0,I3) -> 0 | K3: =ROUNDUP(J3,0) -> 0 | L3: 50 | M3: =L3*K3 -> 0 | N3: =((L3*$L$65)+L3) -> 50 | O3: =N3*K3 -> 0 | P3: =L3/D3 -> 0.125 | Q3: =P3+$M$62+((BC!$F$125)/'c111 DETERMIACION'!$F$32) -> #DIV/0! | R3: =Q3*F3 -> #DIV/0! | S3: =((Q3*0.15)+Q3) -> #DIV/0! | T3: =S3*F3 -> #DIV/0! | U3: =SUM(T3:T31) -> #DIV/0! | V3: =SUM(R3:R31) -> #DIV/0!
A4: =F3+F4+F5+F6+F7+F8+F9+F10+F11+F12+F13+F14+F15+F16+F17+F18+F19+F20+F21+F22+F24+F25+F26+F28 -> 0 | B4: 4657616190 | C4: Urea | D4: 400 | E4: 120 | F4: ='c111'!E10 -> 0 | G4: =F4/D4 -> 0 | H4: =30*BC!B48/E4 -> 0 | I4: =IF(H4>G4,H4,G4) -> 0 | J4: =IF(G4=0,0,I4) -> 0 | K4: =ROUNDUP(J4,0) -> 0 | L4: 62 | M4: =L4*K4 -> 0 | N4: =((L4*$L$65)+L4) -> 62 | O4: =N4*K4 -> 0 | P4: =L4/D4 -> 0.155 | Q4: =P4+$M$62+((BC!$F$125)/'c111 DETERMIACION'!$F$32) -> #DIV/0! | R4: =Q4*F4 -> #DIV/0! | S4: =((Q4*0.15)+Q4) -> #DIV/0! | T4: =S4*F4 -> #DIV/0!
B5: 5401755190 | C5: Creatinina | D5: 400 | E5: 120 | F5: ='c111'!E11 -> 0 | G5: =F5/D5 -> 0 | H5: =30*BC!B49/E5 -> 0 | I5: =IF(H5>G5,H5,G5) -> 0 | J5: =IF(G5=0,0,I5) -> 0 | K5: =ROUNDUP(J5,0) -> 0 | L5: 74 | M5: =L5*K5 -> 0 | N5: =((L5*$L$65)+L5) -> 74 | O5: =N5*K5 -> 0 | P5: =L5/D5 -> 0.185 | Q5: =P5+$M$62+((BC!$F$125)/'c111 DETERMIACION'!$F$32) -> #DIV/0! | R5: =Q5*F5 -> #DIV/0! | S5: =((Q5*0.15)+Q5) -> #DIV/0! | T5: =S5*F5 -> #DIV/0!
B6: 4657608190 | C6: Acido Úrico | D6: 400 | E6: 120 | F6: ='c111'!E12 -> 0 | G6: =F6/D6 -> 0 | H6: =30*BC!B50/E6 -> 0 | I6: =IF(H6>G6,H6,G6) -> 0 | J6: =IF(G6=0,0,I6) -> 0 | K6: =ROUNDUP(J6,0) -> 0 | L6: 89 | M6: =L6*K6 -> 0 | N6: =((L6*$L$65)+L6) -> 89 | O6: =N6*K6 -> 0 | P6: =L6/D6 -> 0.2225 | Q6: =P6+$M$62+((BC!$F$125)/'c111 DETERMIACION'!$F$32) -> #DIV/0! | R6: =Q6*F6 -> #DIV/0! | S6: =((Q6*0.15)+Q6) -> #DIV/0! | T6: =S6*F6 -> #DIV/0!
B7: 4718917190 | C7: Colesterol | D7: 400 | E7: 120 | F7: ='c111'!E13 -> 0 | G7: =F7/D7 -> 0 | H7: =30*BC!B51/E7 -> 0 | I7: =IF(H7>G7,H7,G7) -> 0 | J7: =IF(G7=0,0,I7) -> 0 | K7: =ROUNDUP(J7,0) -> 0 | L7: 83 | M7: =L7*K7 -> 0 | N7: =((L7*$L$65)+L7) -> 83 | O7: =N7*K7 -> 0 | P7: =L7/D7 -> 0.2075 | Q7: =P7+$M$62+((BC!$F$125)/'c111 DETERMIACION'!$F$32) -> #DIV/0! | R7: =Q7*F7 -> #DIV/0! | S7: =((Q7*0.15)+Q7) -> #DIV/0! | T7: =S7*F7 -> #DIV/0!
B8: 4657594190 | C8: Triglicéridos | D8: 200 | E8: 120 | F8: ='c111'!E14 -> 0 | G8: =F8/D8 -> 0 | H8: =30*BC!B52/E8 -> 0 | I8: =IF(H8>G8,H8,G8) -> 0 | J8: =IF(G8=0,0,I8) -> 0 | K8: =ROUNDUP(J8,0) -> 0 | L8: 63 | M8: =L8*K8 -> 0 | N8: =((L8*$L$65)+L8) -> 63 | O8: =N8*K8 -> 0 | P8: =L8/D8 -> 0.315 | Q8: =P8+$M$62+((BC!$F$125)/'c111 DETERMIACION'!$F$32) -> #DIV/0! | R8: =Q8*F8 -> #DIV/0! | S8: =((Q8*0.15)+Q8) -> #DIV/0! | T8: =S8*F8 -> #DIV/0!
B9: 4718569190 | C9: ALT - TGP | D9: 400 | E9: 120 | F9: ='c111'!E15 -> 0 | G9: =F9/D9 -> 0 | H9: =30*BC!B53/E9 -> 0 | I9: =IF(H9>G9,H9,G9) -> 0 | J9: =IF(G9=0,0,I9) -> 0 | K9: =ROUNDUP(J9,0) -> 0 | L9: 103 | M9: =L9*K9 -> 0 | N9: =((L9*$L$65)+L9) -> 103 | O9: =N9*K9 -> 0 | P9: =L9/D9 -> 0.2575 | Q9: =P9+$M$62+((BC!$F$125)/'c111 DETERMIACION'!$F$32) -> #DIV/0! | R9: =Q9*F9 -> #DIV/0! | S9: =((Q9*0.15)+Q9) -> #DIV/0! | T9: =S9*F9 -> #DIV/0!
B10: 4657543190 | C10: AST - TGO | D10: 400 | E10: 120 | F10: ='c111'!E16 -> 0 | G10: =F10/D10 -> 0 | H10: =30*BC!B54/E10 -> 0 | I10: =IF(H10>G10,H10,G10) -> 0 | J10: =IF(G10=0,0,I10) -> 0 | K10: =ROUNDUP(J10,0) -> 0 | L10: 100 | M10: =L10*K10 -> 0 | N10: =((L10*$L$65)+L10) -> 100 | O10: =N10*K10 -> 0 | P10: =L10/D10 -> 0.25 | Q10: =P10+$M$62+((BC!$F$125)/'c111 DETERMIACION'!$F$32) -> #DIV/0! | R10: =Q10*F10 -> #DIV/0! | S10: =((Q10*0.15)+Q10) -> #DIV/0! | T10: =S10*F10 -> #DIV/0!
B11: 4657373190 | C11: Fosfatasa alcalina | D11: 200 | E11: 120 | F11: ='c111'!E17 -> 0 | G11: =F11/D11 -> 0 | H11: =30*BC!B55/E11 -> 0 | I11: =IF(H11>G11,H11,G11) -> 0 | J11: =IF(G11=0,0,I11) -> 0 | K11: =ROUNDUP(J11,0) -> 0 | L11: 107 | M11: =L11*K11 -> 0 | N11: =((L11*$L$65)+L11) -> 107 | O11: =N11*K11 -> 0 | P11: =L11/D11 -> 0.535 | Q11: =P11+$M$62+((BC!$F$125)/'c111 DETERMIACION'!$F$32) -> #DIV/0! | R11: =Q11*F11 -> #DIV/0! | S11: =((Q11*0.15)+Q11) -> #DIV/0! | T11: =S11*F11 -> #DIV/0!
B12: 5795648190 | C12: Bilirrubina Total | D12: 400 | E12: 120 | F12: ='c111'!E18 -> 0 | G12: =F12/D12 -> 0 | H12: =30*BC!B56/E12 -> 0 | I12: =IF(H12>G12,H12,G12) -> 0 | J12: =IF(G12=0,0,I12) -> 0 | K12: =ROUNDUP(J12,0) -> 0 | L12: 78 | M12: =L12*K12 -> 0 | N12: =((L12*$L$65)+L12) -> 78 | O12: =N12*K12 -> 0 | P12: =L12/D12 -> 0.195 | Q12: =P12+$M$62+((BC!$F$125)/'c111 DETERMIACION'!$F$32) -> #DIV/0! | R12: =Q12*F12 -> #DIV/0! | S12: =((Q12*0.15)+Q12) -> #DIV/0! | T12: =S12*F12 -> #DIV/0!
B13: 5589134190 | C13: Bilirrubina Directa | D13: 100 | E13: 60 | F13: ='c111'!E19 -> 0 | G13: =F13/D13 -> 0 | H13: =30*BC!B57/E13 -> #VALUE! | I13: =IF(H13>G13,H13,G13) -> #VALUE! | J13: =IF(G13=0,0,I13) -> 0 | K13: =ROUNDUP(J13,0) -> 0 | L13: 58 | M13: =L13*K13 -> 0 | N13: =((L13*$L$65)+L13) -> 58 | O13: =N13*K13 -> 0 | P13: =L13/D13 -> 0.58 | Q13: =P13+$M$62+((BC!$F$125)/'c111 DETERMIACION'!$F$32) -> #DIV/0! | R13: =Q13*F13 -> #DIV/0! | S13: =((Q13*0.15)+Q13) -> #DIV/0! | T13: =S13*F13 -> #DIV/0!
A14: =SUM(F14+F19) -> 0 | B14: 7528604190 | C14: HDL Colesterol | D14: 200 | E14: 60 | F14: ='c111'!E20 -> 0 | G14: =F14/D14 -> 0 | H14: =30*BC!B58/E14 -> 0 | I14: =IF(H14>G14,H14,G14) -> 0 | J14: =IF(G14=0,0,I14) -> 0 | K14: =ROUNDUP(J14,0) -> 0 | L14: 222 | M14: =L14*K14 -> 0 | N14: =((L14*$L$65)+L14) -> 222 | O14: =N14*K14 -> 0 | P14: =L14/D14 -> 1.11 | Q14: =P14+$M$62+((BC!$F$125)/'c111 DETERMIACION'!$F$32) -> #DIV/0! | R14: =Q14*F14 -> #DIV/0! | S14: =((Q14*0.15)+Q14) -> #DIV/0! | T14: =S14*F14 -> #DIV/0!
B15: 5401496190 | C15: AMILASA | D15: 200 | E15: 60 | F15: ='c111'!E21 -> 0 | G15: =F15/D15 -> 0 | H15: =30*BC!B59/E15 -> 0 | I15: =IF(H15>G15,H15,G15) -> 0 | J15: =IF(G15=0,0,I15) -> 0 | K15: =ROUNDUP(J15,0) -> 0 | L15: 138 | M15: =L15*K15 -> 0 | N15: =((L15*$L$65)+L15) -> 138 | O15: =N15*K15 -> 0 | P15: =L15/D15 -> 0.69 | Q15: =P15+$M$62+((BC!$F$125)/'c111 DETERMIACION'!$F$32) -> #DIV/0! | R15: =Q15*F15 -> #DIV/0! | S15: =((Q15*0.15)+Q15) -> #DIV/0! | T15: =S15*F15 -> #DIV/0!
B16: 5401704190 | C16: LIPASA | D16: 100 | E16: 60 | F16: ='c111'!E22 -> 0 | G16: =F16/D16 -> 0 | H16: =30*BC!B60/E16 -> 36063.015 | I16: =IF(H16>G16,H16,G16) -> 36063.015 | J16: =IF(G16=0,0,I16) -> 0 | K16: =ROUNDUP(J16,0) -> 0 | L16: 132 | M16: =L16*K16 -> 0 | N16: =((L16*$L$65)+L16) -> 132 | O16: =N16*K16 -> 0 | P16: =L16/D16 -> 1.32 | Q16: =P16+$M$62+((BC!$F$125)/'c111 DETERMIACION'!$F$32) -> #DIV/0! | R16: =Q16*F16 -> #DIV/0! | S16: =((Q16*0.15)+Q16) -> #DIV/0! | T16: =S16*F16 -> #DIV/0!
B17: 5401461190 | C17: GGT | D17: 200 | E17: 60 | F17: ='c111'!E23 -> 0 | G17: =F17/D17 -> 0 | H17: =30*BC!B61/E17 -> 0 | I17: =IF(H17>G17,H17,G17) -> 0 | J17: =IF(G17=0,0,I17) -> 0 | K17: =ROUNDUP(J17,0) -> 0 | L17: 67 | M17: =L17*K17 -> 0 | N17: =((L17*$L$65)+L17) -> 67 | O17: =N17*K17 -> 0 | P17: =L17/D17 -> 0.335 | Q17: =P17+$M$62+((BC!$F$125)/'c111 DETERMIACION'!$F$32) -> #DIV/0! | R17: =Q17*F17 -> #DIV/0! | S17: =((Q17*0.15)+Q17) -> #DIV/0! | T17: =S17*F17 -> #DIV/0!
B18: 4657357190 | C18: Albumina | D18: 400 | E18: 120 | F18: ='c111'!E24 -> 0 | G18: =F18/D18 -> 0 | H18: =30*BC!B62/E18 -> #VALUE! | I18: =IF(H18>G18,H18,G18) -> #VALUE! | J18: =IF(G18=0,0,I18) -> 0 | K18: =ROUNDUP(J18,0) -> 0 | L18: 85 | M18: =L18*K18 -> 0 | N18: =((L18*$L$65)+L18) -> 85 | O18: =N18*K18 -> 0 | P18: =L18/D18 -> 0.2125 | Q18: =P18+$M$62+((BC!$F$125)/'c111 DETERMIACION'!$F$32) -> #DIV/0! | R18: =Q18*F18 -> #DIV/0! | S18: =((Q18*0.15)+Q18) -> #DIV/0! | T18: =S18*F18 -> #DIV/0!
B19: 7005806190 | C19: LDL Colesterol | D19: 100 | E19: 60 | F19: ='c111'!E25 -> 0 | G19: =F19/D19 -> 0 | H19: =30*BC!B63/E19 -> #VALUE! | I19: =IF(H19>G19,H19,G19) -> #VALUE! | J19: =IF(G19=0,0,I19) -> 0 | K19: =ROUNDUP(J19,0) -> 0 | L19: 109 | M19: =L19*K19 -> 0 | N19: =((L19*$L$65)+L19) -> 109 | O19: =N19*K19 -> 0 | P19: =L19/D19 -> 1.09 | Q19: =P19+$M$62+((BC!$F$125)/'c111 DETERMIACION'!$F$32) -> #DIV/0! | R19: =Q19*F19 -> #DIV/0! | S19: =((Q19*0.15)+Q19) -> #DIV/0! | T19: =S19*F19 -> #DIV/0!
B20: 5061504190 | C20: Calcio | D20: 400 | E20: 120 | F20: ='c111'!E26 -> 0 | G20: =F20/D20 -> 0 | H20: =30*BC!B64/E20 -> 0 | I20: =IF(H20>G20,H20,G20) -> 0 | J20: =IF(G20=0,0,I20) -> 0 | K20: =ROUNDUP(J20,0) -> 0 | L20: 169 | M20: =L20*K20 -> 0 | N20: =((L20*$L$65)+L20) -> 169 | O20: =N20*K20 -> 0 | P20: =L20/D20 -> 0.4225 | Q20: =P20+$M$62+((BC!$F$125)/'c111 DETERMIACION'!$F$32) -> #DIV/0! | R20: =Q20*F20 -> #DIV/0! | S20: =((Q20*0.15)+Q20) -> #DIV/0! | T20: =S20*F20 -> #DIV/0!
B21: 7442017190 | C21: CK | D21: 200 | E21: 60 | F21: ='c111'!E27 -> 0 | G21: =F21/D21 -> 0 | H21: =30*BC!B65/E21 -> 0 | I21: =IF(H21>G21,H21,G21) -> 0 | J21: =IF(G21=0,0,I21) -> 0 | K21: =ROUNDUP(J21,0) -> 0 | L21: 140 | M21: =L21*K21 -> 0 | N21: =((L21*$L$65)+L21) -> 140 | O21: =N21*K21 -> 0 | P21: =L21/D21 -> 0.7 | Q21: =P21+$M$62+((BC!$F$125)/'c111 DETERMIACION'!$F$32) -> #DIV/0! | R21: =Q21*F21 -> #DIV/0! | S21: =((Q21*0.15)+Q21) -> #DIV/0! | T21: =S21*F21 -> #DIV/0!
B22: 5401674190 | C22: LDH | D22: 100 | E22: 60 | F22: ='c111'!E28 -> 0 | G22: =F22/D22 -> 0 | H22: =30*BC!B66/E22 -> 0 | I22: =IF(H22>G22,H22,G22) -> 0 | J22: =IF(G22=0,0,I22) -> 0 | K22: =ROUNDUP(J22,0) -> 0 | L22: 128 | M22: =L22*K22 -> 0 | N22: =((L22*$L$65)+L22) -> 128 | O22: =N22*K22 -> 0 | P22: =L22/D22 -> 1.28 | Q22: =P22+$M$62+((BC!$F$125)/'c111 DETERMIACION'!$F$32) -> #DIV/0! | R22: =Q22*F22 -> #DIV/0! | S22: =((Q22*0.15)+Q22) -> #DIV/0! | T22: =S22*F22 -> #DIV/0!
B23: 5336180190 | C23: HbA1c | D23: 200 | E23: 60 | F23: ='c111'!E29 -> 0 | G23: =F23/D23 -> 0 | H23: =30*BC!B67/E23 -> 0 | I23: =IF(H23>G23,H23,G23) -> 0 | J23: =IF(G23=0,0,I23) -> 0 | K23: =ROUNDUP(J23,0) -> 0 | L23: 310 | M23: =L23*K23 -> 0 | N23: =((L23*$L$65)+L23) -> 310 | O23: =N23*K23 -> 0 | P23: =L23/D23 -> 1.55 | Q23: =P23+$M$62+((BC!$F$125)/'c111 DETERMIACION'!$F$32) -> #DIV/0! | R23: =Q23*F23 -> #DIV/0! | S23: =((Q23*0.15)+Q23) -> #DIV/0! | T23: =S23*F23 -> #DIV/0!
B24: 5401658190 | C24: Hierro | D24: 100 | E24: 60 | F24: ='c111'!E30 -> 0 | G24: =F24/D24 -> 0 | H24: =30*BC!B68/E24 -> 0 | I24: =IF(H24>G24,H24,G24) -> 0 | J24: =IF(G24=0,0,I24) -> 0 | K24: =ROUNDUP(J24,0) -> 0 | L24: 87 | M24: =L24*K24 -> 0 | N24: =((L24*$L$65)+L24) -> 87 | O24: =N24*K24 -> 0 | P24: =L24/D24 -> 0.87 | Q24: =P24+$M$62+((BC!$F$125)/'c111 DETERMIACION'!$F$32) -> #DIV/0! | R24: =Q24*F24 -> #DIV/0! | S24: =((Q24*0.15)+Q24) -> #DIV/0! | T24: =S24*F24 -> #DIV/0!
B25: 4657586190 | C25: Proteinas totales | D25: 400 | E25: 120 | F25: ='c111'!E31 -> 0 | G25: =F25/D25 -> 0 | H25: =30*BC!B69/E25 -> 0 | I25: =IF(H25>G25,H25,G25) -> 0 | J25: =IF(G25=0,0,I25) -> 0 | K25: =ROUNDUP(J25,0) -> 0 | L25: 80 | M25: =L25*K25 -> 0 | N25: =((L25*$L$65)+L25) -> 80 | O25: =N25*K25 -> 0 | P25: =L25/D25 -> 0.2 | Q25: =P25+$M$62+((BC!$F$125)/'c111 DETERMIACION'!$F$32) -> #DIV/0! | R25: =Q25*F25 -> #DIV/0! | S25: =((Q25*0.15)+Q25) -> #DIV/0! | T25: =S25*F25 -> #DIV/0!
B26: 7876432190 | C26: PCR latex | D26: 200 | E26: 60 | F26: ='c111'!E32 -> 0 | G26: =F26/D26 -> 0 | H26: =30*BC!B70/E26 -> 0 | I26: =IF(H26>G26,H26,G26) -> 0 | J26: =IF(G26=0,0,I26) -> 0 | K26: =ROUNDUP(J26,0) -> 0 | L26: 180 | M26: =L26*K26 -> 0 | N26: =((L26*$L$65)+L26) -> 180 | O26: =N26*K26 -> 0 | P26: =L26/D26 -> 0.9 | Q26: =P26+$M$62+((BC!$F$125)/'c111 DETERMIACION'!$F$32) -> #DIV/0! | R26: =Q26*F26 -> #DIV/0! | S26: =((Q26*0.15)+Q26) -> #DIV/0! | T26: =S26*F26 -> #DIV/0!
... B30: 8900019190 | C30: MG2, 100T, COBAS C 111 | D30: 100 | E30: 56 | F30: ='c111'!E36 -> 0 | G30: =F30/D30 -> 0 | H30: =30*BC!B74/E30 -> 0 | I30: =IF(H30>G30,H30,G30) -> 0 | J30: =IF(G30=0,0,I30) -> 0 | K30: =ROUNDUP(J30,0) -> 0 | L30: 90 | M30: =L30*K30 -> 0 | N30: =((L30*$L$65)+L30) -> 90 | O30: =N30*K30 -> 0 | P30: =L30/D30 -> 0.9 | Q30: =P30+$M$62+((BC!$F$125)/'c111 DETERMIACION'!$F$32) -> #DIV/0! | R30: =Q30*F30 -> #DIV/0! | S30: =((Q30*0.15)+Q30) -> #DIV/0! | T30: =S30*F30 -> #DIV/0!
B31: 7442050190 | C31: CK-MB | D31: 100 | E31: 60 | F31: ='c111'!E37 -> 0 | G31: =F31/D31 -> 0 | H31: =30*BC!B74/E31 -> 0 | I31: =IF(H31>G31,H31,G31) -> 0 | J31: =IF(G31=0,0,I31) -> 0 | K31: =ROUNDUP(J31,0) -> 0 | L31: 164 | M31: =L31*K31 -> 0 | N31: =((L31*$L$65)+L31) -> 164 | O31: =N31*K31 -> 0 | P31: =L31/D31 -> 1.64 | Q31: =P31+$M$62+((BC!$F$125)/'c111 DETERMIACION'!$F$32) -> #DIV/0! | R31: =Q31*F31 -> #DIV/0! | S31: =((Q31*0.15)+Q31) -> #DIV/0! | T31: =S31*F31 -> #DIV/0!
D32: TOTAL DET | F32: =SUM(F3:F31) -> 0 | M32: =SUM(M3:M31)+M61 -> 4940 | O32: =SUM(O3:O31)+P60 -> 520.37222
B33: CALIBRADOR | D33: PRESENTACION | E33: DIAS ESTABILIDAD | G33: PRODUCTO CALCULADO | H33: MINIMOS POR ESTABILIDAD | I33: PRODUCTO A ENTREGAR | K33: MAXIMOS | L33: PVP POR UDS | M33: VALOR TOTAL | N33: PVP TODO COMPRADO CAJA | O33: PVP TODO COMPRADO POR UDS | P33: TOTAL PVP TODO COMPRADO POR UDS
B34: 10759350190 | C34: Calibrator f.a.s. 12x3 ml | D34: 12 | E34: 28 | G34: =(A4/(0.005*400)/3000) -> 0 | H34: =30*BC!$B$47/E34 -> 0 | I34: =IF(G34>H34,G34,H34) -> 0 | J34: =ROUNDUP(I34,0) -> 0 | K34: 1 | L34: =M34/D34 -> 12 | M34: 144 | N34: =O34*D34 -> 144 | O34: =((L34*$L$65)+L34) -> 12 | P34: =O34*K34 -> 12
B35: 12172623122 | C35: Cfas Lipids 3x1ML | D35: 3 | E35: 28 | G35: =(A10*(0.008*(350/1000))) -> 0 | H35: =30*BC!$B$47/E35 -> 0 | I35: =IF(G35>H35,G35,H35) -> 0 | J35: =ROUNDUP(I35,0) -> 0 | K35: 1 | L35: =M35/D35 -> 31 | M35: 93 | N35: =O35*D35 -> 93 | O35: =((L35*$L$65)+L35) -> 31 | P35: =O35*K35 -> 31
B36: 11355279216 | C36: Cfas Proteins | D36: 5 | E36: 28 | G36: =(F26*(0.014*(500/2000))) -> 0 | H36: =30*BC!$B$47/E36 -> 0 | I36: =IF(G36>H36,G36,H36) -> 0 | J36: =ROUNDUP(I36,0) -> 0 | K36: 1 | L36: =M36/D36 -> 29.8 | M36: 149 | N36: =O36*D36 -> 149 | O36: =((L36*$L$65)+L36) -> 29.8 | P36: =O36*K36 -> 29.8
B37: 4528417190 | C37: Cfas HbA1c, 3x2ml | D37: 3 | E37: 84 | G37: =(F23*(0.014*(500/2000))) -> 0 | H37: =30*BC!$B$47/E37 -> 0 | I37: =IF(G37>H37,G37,H37) -> 0 | J37: =ROUNDUP(I37,0) -> 0 | L37: =M37/D37 -> 150.33333 | M37: 451 | N37: =O37*D37 -> 451 | O37: =((L37*$L$65)+L37) -> 150.33333 | P37: =O37*K37 -> 0
B38: 20751995190 | C38: Ammonia/Ethanol/CO2 Calibrator | D38: 2 | E38: 56 | G38: =(F29*(0.014*(500/2000))) -> 0 | H38: =30*BC!$B$47/E38 -> 0 | I38: =IF(G38>H38,G38,H38) -> 0 | J38: =ROUNDUP(I38,0) -> 0 | K38: =IF(F24>0,J38,0) -> 0 | L38: =M38/D38 -> 313.5 | M38: 627 | N38: =O38*D38 -> 627 | O38: =((L38*$L$65)+L38) -> 313.5 | P38: =O38*K38 -> 0
B39: 5050901190 | C39: Cfas D- Dimer | D39: 1 | E39: 84 | G39: =(F27*(0.014*(500/2000))) -> 0 | H39: =30*BC!$B$47/E39 -> 0 | I39: =IF(G39>H39,G39,H39) -> 0 | J39: =ROUNDUP(I39,0) -> 0 | L39: =M39/D39 -> 282 | M39: 282 | N39: =O39*D39 -> 282 | O39: =((L39*$L$65)+L39) -> 282 | P39: =O39*K39 -> 0
B40: 11447394216 | C40: Calibrator f.a.s. CK‑MB | D40: 3 | E40: 28 | G40: =(F31*(0.014*(500/2000))) -> 0 | H40: =30*BC!$B$47/E40 -> 0 | I40: =IF(G40>H40,G40,H40) -> 0 | J40: =ROUNDUP(I40,0) -> 0 | K40: =IF(F28>0,J40,0) -> 0 | L40: =M40/D40 -> 25.333333 | M40: 76 | N40: =O40*D40 -> 76 | O40: =((L40*$L$65)+L40) -> 25.333333 | P40: =ROUNDUP(O40,0) -> 26
B41: CONTROL | N41: =O41*D41 -> 0 | O41: =((L41*$L$65)+L41) -> 0
B42: 5947626190 | C42: PreciControl ClinChem Multi 1 4x5ml | D42: 4 | E42: 14 | G42: =(A7/(0.003*350)/5000) -> 0 | H42: =30*BC!$B$47/E42 -> 0 | I42: =IF(G42>H42,G42,H42) -> 0 | J42: =ROUNDUP(I42,0) -> 0 | K42: 1 | L42: =M42/D42 -> 14.25 | M42: 57 | N42: =O42*D42 -> 57 | O42: =((L42*$L$65)+L42) -> 14.25 | P42: =O42*K42 -> 14.25
B43: 5947774190 | C43: PreciControl ClinChem Multi 2 4x5ml | D43: 4 | E43: 14 | G43: =(A7/(0.003*350)/5000) -> 0 | H43: =30*BC!$B$47/E43 -> 0 | I43: =IF(G43>H43,G43,H43) -> 0 | J43: =ROUNDUP(I43,0) -> 0 | K43: 1 | L43: =M43/D43 -> 22.75 | M43: 91 | N43: =O43*D43 -> 91 | O43: =((L43*$L$65)+L43) -> 22.75 | P43: =O43*K43 -> 22.75
B44: 5479207190 | C44: PreciControl HBA1c Norm | D44: 4 | E44: 28 | G44: =(F23/(0.0007*150)/1000) -> 0 | H44: =30*BC!$B$47/E44 -> 0 | I44: =IF(G44>H44,G44,H44) -> 0 | J44: =ROUNDUP(I44,0) -> 0 | L44: =M44/D44 -> 77.25 | M44: 309 | N44: =O44*D44 -> 309 | O44: =((L44*$L$65)+L44) -> 77.25 | P44: =O44*K44 -> 0
...

Sheet c311
A1: CLIENTE
A2: FECHA
A3: MODALIDAD
A4: PLAZO | C4: MESES
A5: PROYECCIÓN | C5: MESES
A6: EQUIPO | B6: C311
A8: I.D | B8: DESCRIPCION | C8: DET/KIT | D8: DIAS ESTABILIDAD | E8: DET/AÑO/PROCESO | F8: PRODUCTO CALCULADO | G8: MINIMOS POR ESTABILIDAD | H8: PRODUCTO A ENTREGAR
A9: 6750052190 | B9: A-1MG TQ GEN.2, 100TEST, COBAS C/INT | C9: 200 | D9: 84 | F9: =E9/C9 -> 0 | G9: =365/D9 -> 4.3452381
A10: 3005771322 | B10: AAT GEN.2, 100TESTS, COBAS C, INTEGRA | C10: 100 | D10: 84 | F10: =E10/C10 -> 0 | G10: =365/D10 -> 4.3452381
A11: 4375351190 | B11: ACP HIT 917 LARGE | C11: 400 | D11: 84 | F11: =E11/C11 -> 0 | G11: =365/D11 -> 4.3452381
A12: 3183688122 | B12: ALB2, 300T, COBAS C, INTEGRA | C12: 300 | D12: 84 | F12: =E12/C12 -> 0 | G12: =365/D12 -> 4.3452381
A13: 4469658190 | B13: ALB-T TQ GEN.2, 100TESTS, COBAS C, INT | C13: 100 | D13: 84 | F13: =E13/C13 -> 0 | G13: =365/D13 -> 4.3452381
A14: 3333752190 | B14: ALP2, 200T, COBAS C, INTEGRA | C14: 200 | D14: 56 | F14: =E14/C14 -> 0 | G14: =365/D14 -> 6.5178571
A15: 20764957322 | B15: ALTL, 500TESTS, COBAS C, INTEGRA | C15: 500 | D15: 84 | F15: =E15/C15 -> 0 | G15: =365/D15 -> 4.3452381
A16: 3183742122 | B16: AMYL GEN.2, 300TESTS, COBAS C, INTEGRA | C16: 300 | D16: 84 | F16: =E16/C16 -> 0 | G16: =365/D16 -> 4.3452381
A17: 3032566122 | B17: APOAT, 100TESTS, COBAS C, INTEGRA | C17: 100 | D17: 84 | F17: =E17/C17 -> 0 | G17: =365/D17 -> 4.3452381
A18: 3032574122 | B18: APOBT, 100TESTS, COBAS C, INTEGRA | C18: 100 | D18: 84 | F18: =E18/C18 -> 0 | G18: =365/D18 -> 4.3452381
A19: 4489403190 | B19: ASLO TQ, 150TESTS, COBAS C | C19: 150 | D19: 84 | F19: =E19/C19 -> 0 | G19: =365/D19 -> 4.3452381
A20: 20764949322 | B20: ASTL, 500TESTS, COBAS C, INTEGRA | C20: 500 | D20: 84 | F20: =E20/C20 -> 0 | G20: =365/D20 -> 4.3452381
... A73: 4460715190 | B73: UREAL, 500T, COBAS C, INTEGRA | C73: 500 | D73: 56 | F73: =E73/C73 -> 0 | G73: =365/D73 -> 6.5178571
D74: TOTAL DET | E74: =SUM(E9:E73) -> 0
B75: CALIBRADORES | D75: DIAS ESTABILIDAD | F75: PRODUCTO CALCULADO | G75: MINIMOS POR ESTABILIDAD | H75: PRODUCTO A ENTREGAR
A76: 20751995190 | B76: Ammonia/Ethanol/CO2 Calibrator | C76: 2 | D76: 56 | G76: =(365/D76)/C76 -> 3.2589286
A77: 4975901190 | B77: C.f.a.s. Cystatin C | C77: 1 | G77: =(365/D77)/C77 -> #DIV/0!
A78: 3555941190 | B78: C.f.a.s. PAC | C78: 3 | D78: 14 | G78: =(365/D78)/C78 -> 8.6904762
A79: 10759350190 | B79: Calibrator f.a.s. | C79: 12 | D79: 28 | G79: =(365/D79)/C79 -> 1.0863095
A80: 11447394216 | B80: Calibrator f.a.s. CK-MB | C80: 3 | D80: 28 | G80: =(365/D80)/C80 -> 4.3452381
A81: 6533850190 | B81: Calibrator f.a.s. IgA/IgM CSF | C81: 3 | D81: 14 | G81: =(365/D81)/C81 -> 8.6904762
A82: 12172623122 | B82: Calibrator f.a.s. Lipids | C82: 3 | D82: 28 | G82: =(365/D82)/C82 -> 4.3452381
A83: 11355279216 | B83: Calibrator f.a.s.proteins | C83: 5 | D83: 28 | G83: =(365/D83)/C83 -> 2.6071429
A84: 8753776190 | B84: CALIBRATOR STFR GEN.2 | C84: 3 | D84: 28 | G84: =(365/D84)/C84 -> 4.3452381
A85: 8047545190 | B85: Calibrator β2‑Microglobulin | C85: 2 | D85: 84 | G85: =(365/D85)/C85 -> 2.172619
A86: 4528417190 | B86: Cfas HbA1c | C86: 3 | D86: 84 | G86: =(365/D86)/C86 -> 1.4484127
A87: 3121305122 | B87: Cfas Proteins U | C87: 5 | D87: 28 | G87: =(365/D87)/C87 -> 2.6071429
A88: 5050901190 | B88: D-Dimer Gen.2 Calibrator Set | C88: 1 | D88: 84 | G88: =(365/D88)/C88 -> 4.3452381
A89: 12146401216 | B89: Fe Standard | C89: 1 | D89: 360 | G89: =(365/D89)/C89 -> 1.0138889
... A94: 12172828322 | B94: Preciset RF | C94: 1 | D94: 30 | G94: =(365/D94)/C94 -> 12.166667
B95: CONTROLES | C95: PRESENTACION | D95: DIAS ESTABILIDAD | F95: PRODUCTO CALCULADO | G95: MINIMOS POR ESTABILIDAD | H95: PRODUCTO A ENTREGAR
A96: 20752401190 | B96: Ammonia/Ethanol/CO2 Control Normal | C96: 5 | D96: 56 | G96: =(365/D96)/C96 -> 1.3035714
A97: 20753009190 | B97: Ammonia/Ethanol/CO2 Control Abnormal | C97: 5 | D97: 56 | G97: =(365/D97)/C97 -> 1.3035714
...

Sheet c311 DETERMINACION
B1: CLIENTE
B2: FECHA
B3: MODALIDAD
B4: PLAZO | D4: MESES
B5: PROYECCIÓN | D5: MESES
B6: EQUIPO | C6: C311
B8: I.D | C8: DESCRIPCION | D8: DET/KIT | E8: DIAS ESTABILIDAD | F8: DET/AÑO/PROCESO | G8: PRODUCTO CALCULADO | H8: MINIMOS POR ESTABILIDAD | I8: PRODUCTO A ENTREGAR | K8: REDONDEADO A ENTREGAR | L8: PVP | M8: TOTAL | N8: $ DETERMINACION | O8: $DETERMINACION CON CONSUMIBLES Y EXTRAS | P8: TOTAL CON CONSUMIBLES Y EXTRAS | Q8: $ PARA PROCESO | R8: TOTAL PARA PROCESO | S8: VALOR INICIAL DEL PROCESO | T8: VALOR FINAL DEL PROCESO
A9: CFAS | B9: 6750052190 | C9: A-1MG TQ GEN.2, 100TEST, COBAS C/INT | D9: 200 | E9: 84 | F9: ='c311'!E9 -> 0 | G9: =F9/D9 -> 0 | H9: =30*BC!B47/E9 -> 0 | I9: =IF(H9>G9,H9,G9) -> 0 | J9: =IF(G9=0,0,I9) -> 0 | K9: =ROUNDUP(J9,0) -> 0 | L9: 762 | M9: =L9*K9 -> 0 | N9: =L9/D9 -> 3.81 | O9: =N9+$N$137+((BC!$F$125)/$F$74) -> #DIV/0! | P9: =O9*F9 -> #DIV/0! | Q9: =((O9*0.15)+O9) -> #DIV/0! | R9: =Q9*F9 -> #DIV/0! | S9: =SUM(R9:R73) -> #DIV/0! | T9: =SUM(P9:P73) -> #DIV/0!
A10: =F11+F12+F14+F15+F16+F20+F22+F23+F26+F28+F29+F30+F34+F41+F42+F45+F52+F54+F56+F58+F60+F62+F67+F69+F71+F73 -> 0 | B10: 3005771322 | C10: AAT GEN.2, 100TESTS, COBAS C, INTEGRA | D10: 100 | E10: 84 | F10: ='c311'!E10 -> 0 | G10: =F10/D10 -> 0 | H10: =30*BC!B48/E10 -> 0 | I10: =IF(H10>G10,H10,G10) -> 0 | J10: =IF(G10=0,0,I10) -> 0 | K10: =ROUNDUP(J10,0) -> 0 | L10: 436 | M10: =L10*K10 -> 0 | N10: =L10/D10 -> 4.36 | O10: =N10+$N$137+((BC!$F$125)/$F$74) -> #DIV/0! | P10: =O10*F10 -> #DIV/0! | Q10: =((O10*0.15)+O10) -> #DIV/0! | R10: =Q10*F10 -> #DIV/0!
B11: 4375351190 | C11: ACP HIT 917 LARGE | D11: 400 | E11: 84 | F11: ='c311'!E11 -> 0 | G11: =F11/D11 -> 0 | H11: =30*BC!B49/E11 -> 0 | I11: =IF(H11>G11,H11,G11) -> 0 | J11: =IF(G11=0,0,I11) -> 0 | K11: =ROUNDUP(J11,0) -> 0 | L11: 456 | M11: =L11*K11 -> 0 | N11: =L11/D11 -> 1.14 | O11: =N11+$N$137+((BC!$F$125)/$F$74) -> #DIV/0! | P11: =O11*F11 -> #DIV/0! | Q11: =((O11*0.15)+O11) -> #DIV/0! | R11: =Q11*F11 -> #DIV/0!
A12: CCLINCHEM | B12: 3183688122 | C12: ALB2, 300T, COBAS C, INTEGRA | D12: 300 | E12: 84 | F12: ='c311'!E12 -> 0 | G12: =F12/D12 -> 0 | H12: =30*BC!B50/E12 -> 0 | I12: =IF(H12>G12,H12,G12) -> 0 | J12: =IF(G12=0,0,I12) -> 0 | K12: =ROUNDUP(J12,0) -> 0 | L12: 72 | M12: =L12*K12 -> 0 | N12: =L12/D12 -> 0.24 | O12: =N12+$N$137+((BC!$F$125)/$F$74) -> #DIV/0! | P12: =O12*F12 -> #DIV/0! | Q12: =((O12*0.15)+O12) -> #DIV/0! | R12: =Q12*F12 -> #DIV/0!
